<?xml version="1.0" encoding="UTF-8"?>
<robot name="gbt-c5a">
  <joint name="AssemblerFixedJoint" type="fixed">
    <origin xyz="0. 0. 0." rpy="0. 0.0000002 1.5707964"/>
    <parent link="gbt_c5a_gripper_link6"/>
    <child link="ee_link_robotiq_arg2f_base_link"/>
  </joint>
  <joint name="finger_joint" type="revolute">
    <origin xyz="0. -0.030601 0.054905" rpy="-2.2957964 0. -3.1415927"/>
    <parent link="ee_link_robotiq_arg2f_base_link"/>
    <child link="left_outer_knuckle"/>
    <axis xyz="1. 0. 0."/>
    <limit lower="0." upper="0.7" effort="200." velocity="1.9999999"/>
  </joint>
  <joint name="joint1" type="revolute">
    <origin xyz="0. 0. 0.178" rpy="0. 0. 0."/>
    <parent link="gbt_c5a_gripper_base_link"/>
    <child link="gbt_c5a_gripper_link1"/>
    <axis xyz="0. 0. 1."/>
    <limit lower="-6.2831853" upper="6.2831853" effort="100." velocity="0.9999999"/>
  </joint>
  <joint name="joint2" type="revolute">
    <origin xyz="0. 0.147 0. " rpy="1.5707964 0. 0. "/>
    <parent link="gbt_c5a_gripper_link1"/>
    <child link="gbt_c5a_gripper_link2"/>
    <axis xyz="0. 0. 1."/>
    <limit lower="-1.4835297" upper="4.6251225" effort="100." velocity="0.9999999"/>
  </joint>
  <joint name="joint3" type="revolute">
    <origin xyz="0.425 -0. 0.072" rpy="0. 0. 0."/>
    <parent link="gbt_c5a_gripper_link2"/>
    <child link="gbt_c5a_gripper_link3"/>
    <axis xyz="0. 0. 1."/>
    <limit lower="-2.879793" upper="2.879793" effort="100." velocity="0.9999999"/>
  </joint>
  <joint name="joint4" type="revolute">
    <origin xyz="0.385 0. -0.052" rpy="0. 0. 0."/>
    <parent link="gbt_c5a_gripper_link3"/>
    <child link="gbt_c5a_gripper_link4"/>
    <axis xyz="0. 0. 1."/>
    <limit lower="-1.4835297" upper="4.6251225" effort="100." velocity="0.9999999"/>
  </joint>
  <joint name="joint5" type="revolute">
    <origin xyz="-0. -0.1233 0. " rpy="1.5707964 0. 0. "/>
    <parent link="gbt_c5a_gripper_link4"/>
    <child link="gbt_c5a_gripper_link5"/>
    <axis xyz="0. 0. 1."/>
    <limit lower="-6.2831853" upper="6.2831853" effort="100." velocity="0.9999999"/>
  </joint>
  <joint name="joint6" type="revolute">
    <origin xyz="0. -0.1003 -0. " rpy="1.5707963 0. 0. "/>
    <parent link="gbt_c5a_gripper_link5"/>
    <child link="gbt_c5a_gripper_link6"/>
    <axis xyz="0. 0. 1."/>
    <limit lower="-6.2831853" upper="6.2831853" effort="100." velocity="0.9999999"/>
  </joint>
  <joint name="left_inner_finger_joint" type="revolute">
    <origin xyz="0. -0.0999754 -0.0022185" rpy="-0.725 0. 3.1415927"/>
    <parent link="left_outer_knuckle"/>
    <child link="left_inner_finger"/>
    <axis xyz="1. 0. 0."/>
    <limit lower="-0.14" upper="0.84" effort="0." velocity="17453.2925199"/>
  </joint>
  <joint name="left_inner_knuckle_joint" type="revolute">
    <origin xyz="0. -0.0127 0.06142" rpy="2.2957964 0. 0. "/>
    <parent link="ee_link_robotiq_arg2f_base_link"/>
    <child link="left_inner_knuckle"/>
    <axis xyz="1. 0. 0."/>
    <limit lower="-0.84" upper="0.14" effort="0." velocity="17453.2925199"/>
  </joint>
  <joint name="right_inner_finger_joint" type="revolute">
    <origin xyz="0. 0.0999754 -0.0022185" rpy="-0.725 0. 0. "/>
    <parent link="right_outer_knuckle"/>
    <child link="right_inner_finger"/>
    <axis xyz="1. 0. 0."/>
    <limit lower="-0.14" upper="0.84" effort="0." velocity="17453.2925199"/>
  </joint>
  <joint name="right_inner_knuckle_joint" type="revolute">
    <origin xyz="0. 0.0127 0.06142" rpy="2.2957964 0. 3.1415925"/>
    <parent link="ee_link_robotiq_arg2f_base_link"/>
    <child link="right_inner_knuckle"/>
    <axis xyz="1. 0. 0."/>
    <limit lower="-0.84" upper="0.14" effort="0." velocity="17453.2925199"/>
  </joint>
  <joint name="right_outer_knuckle_joint" type="revolute">
    <origin xyz="0. 0.030601 0.054905" rpy="2.2957964 0. -3.1415925"/>
    <parent link="ee_link_robotiq_arg2f_base_link"/>
    <child link="right_outer_knuckle"/>
    <axis xyz="1. 0. 0."/>
    <limit lower="-0.84" upper="0.14" effort="0." velocity="17453.2925199"/>
  </joint>
  <joint name="root_joint" type="fixed">
    <origin xyz="0. 0. 0." rpy="0. 0. 0."/>
    <parent link="gbt_c5a_gripper"/>
    <child link="gbt_c5a_gripper_base_link"/>
  </joint>
  <link name="ee_link_robotiq_arg2f_base_link">
    <inertial>
      <origin xyz="0.0000001 -0.0000047 0.03145 " rpy="0. 0. 0."/>
      <mass value="0.22652"/>
      <inertia ixx="0.0002" ixy="-0." ixz="-0." iyy="0.0001783" iyz="-0." izz="0.0001348"/>
    </inertial>
    <visual>
      <origin xyz="0. 0. 0." rpy="0. 0. 0."/>
      <geometry>
        <mesh filename="/home/gbt/isaacsim5.0/meshes/ee_link_robotiq_arg2f_base_link_visuals_robotiq_arg2f_base_link_mesh.obj" scale="1. 1. 1."/>
      </geometry>
    </visual>
    <visual>
      <origin xyz="0. 0. 0." rpy="0. 0. 0."/>
      <geometry>
        <mesh filename="/home/gbt/isaacsim5.0/meshes/ee_link_robotiq_arg2f_base_link_collisions_robotiq_arg2f_base_link_mesh.obj" scale="1. 1. 1."/>
      </geometry>
    </visual>
    <collision>
      <origin xyz="0. 0. 0." rpy="0. 0. 0."/>
      <geometry>
        <mesh filename="/home/gbt/isaacsim5.0/meshes/ee_link_robotiq_arg2f_base_link_collisions_robotiq_arg2f_base_link_mesh.obj" scale="1. 1. 1."/>
      </geometry>
    </collision>
  </link>
  <link name="gbt_c5a_gripper"/>
  <link name="gbt_c5a_gripper_base_link">
    <inertial>
      <origin xyz="-0.000115 -0.003836 0.044852" rpy="0. 0. 0."/>
      <mass value="1.489536"/>
      <inertia ixx="0.004543" ixy="-0.000001" ixz="-0.000011" iyy="0.003119" iyz="0.000197" izz="0.0058"/>
    </inertial>
    <visual>
      <origin xyz="0. 0. 0." rpy="0. 0. 0."/>
      <geometry>
        <mesh filename="/home/gbt/isaacsim5.0/meshes/gbt_c5a_gripper_base_link_visuals_base_link_mesh.obj" scale="1. 1. 1."/>
      </geometry>
    </visual>
    <visual>
      <origin xyz="0. 0. 0." rpy="0. 0. 0."/>
      <geometry>
        <mesh filename="/home/gbt/isaacsim5.0/meshes/gbt_c5a_gripper_base_link_collisions_base_link_mesh.obj" scale="1. 1. 1."/>
      </geometry>
    </visual>
    <collision>
      <origin xyz="0. 0. 0." rpy="0. 0. 0."/>
      <geometry>
        <mesh filename="/home/gbt/isaacsim5.0/meshes/gbt_c5a_gripper_base_link_collisions_base_link_mesh.obj" scale="1. 1. 1."/>
      </geometry>
    </collision>
  </link>
  <link name="gbt_c5a_gripper_link1">
    <inertial>
      <origin xyz="-0.000366 0.00196 -0.027035" rpy="0. 0. 0."/>
      <mass value="4.7630582"/>
      <inertia ixx="0.010679" ixy="0.00004" ixz="-0.000058" iyy="0.010619" iyz="0.000214" izz="0.008154"/>
    </inertial>
    <visual>
      <origin xyz="0. 0. 0." rpy="0. 0. 0."/>
      <geometry>
        <mesh filename="/home/gbt/isaacsim5.0/meshes/gbt_c5a_gripper_link1_visuals_link1_mesh.obj" scale="1. 1. 1."/>
      </geometry>
    </visual>
    <visual>
      <origin xyz="0. 0. 0." rpy="0. 0. 0."/>
      <geometry>
        <mesh filename="/home/gbt/isaacsim5.0/meshes/gbt_c5a_gripper_link1_collisions_link1_mesh.obj" scale="1. 1. 1."/>
      </geometry>
    </visual>
    <collision>
      <origin xyz="0. 0. 0." rpy="0. 0. 0."/>
      <geometry>
        <mesh filename="/home/gbt/isaacsim5.0/meshes/gbt_c5a_gripper_link1_collisions_link1_mesh.obj" scale="1. 1. 1."/>
      </geometry>
    </collision>
  </link>
  <link name="gbt_c5a_gripper_link2">
    <inertial>
      <origin xyz="0.212421 0. 0.023494" rpy="0. 0. 0."/>
      <mass value="10.9228296"/>
      <inertia ixx="0.025117" ixy="0.000815" ixz="0.000075" iyy="0.463693" iyz="0.000001" izz="0.457686"/>
    </inertial>
    <visual>
      <origin xyz="0. 0. 0." rpy="0. 0. 0."/>
      <geometry>
        <mesh filename="/home/gbt/isaacsim5.0/meshes/gbt_c5a_gripper_link2_visuals_link2_mesh.obj" scale="1. 1. 1."/>
      </geometry>
    </visual>
    <visual>
      <origin xyz="0. 0. 0." rpy="0. 0. 0."/>
      <geometry>
        <mesh filename="/home/gbt/isaacsim5.0/meshes/gbt_c5a_gripper_link2_collisions_link2_mesh.obj" scale="1. 1. 1."/>
      </geometry>
    </visual>
    <collision>
      <origin xyz="0. 0. 0." rpy="0. 0. 0."/>
      <geometry>
        <mesh filename="/home/gbt/isaacsim5.0/meshes/gbt_c5a_gripper_link2_collisions_link2_mesh.obj" scale="1. 1. 1."/>
      </geometry>
    </collision>
  </link>
  <link name="gbt_c5a_gripper_link3">
    <inertial>
      <origin xyz="0.240843 -0.000259 0.057044" rpy="0. 0. 0."/>
      <mass value="3.817807"/>
      <inertia ixx="0.006786" ixy="-0.000147" ixz="-0.001424" iyy="0.104226" iyz="-0.000012" izz="0.102926"/>
    </inertial>
    <visual>
      <origin xyz="-0. 0. -0." rpy="0. 0. 0."/>
      <geometry>
        <mesh filename="/home/gbt/isaacsim5.0/meshes/gbt_c5a_gripper_link3_visuals_link3_mesh.obj" scale="1. 1. 1."/>
      </geometry>
    </visual>
    <visual>
      <origin xyz="-0. 0. -0." rpy="0. 0. 0."/>
      <geometry>
        <mesh filename="/home/gbt/isaacsim5.0/meshes/gbt_c5a_gripper_link3_collisions_link3_mesh.obj" scale="1. 1. 1."/>
      </geometry>
    </visual>
    <collision>
      <origin xyz="-0. 0. -0." rpy="0. 0. 0."/>
      <geometry>
        <mesh filename="/home/gbt/isaacsim5.0/meshes/gbt_c5a_gripper_link3_collisions_link3_mesh.obj" scale="1. 1. 1."/>
      </geometry>
    </collision>
  </link>
  <link name="gbt_c5a_gripper_link4">
    <inertial>
      <origin xyz="0.000527 -0.017542 -0.002802" rpy="0. 0. 0."/>
      <mass value="1.860492"/>
      <inertia ixx="0.003113" ixy="0.000018" ixz="-0.000009" iyy="0.01678" iyz="0.000064" izz="0.002995"/>
    </inertial>
    <visual>
      <origin xyz="-0. -0. 0." rpy="0. 0. 0."/>
      <geometry>
        <mesh filename="/home/gbt/isaacsim5.0/meshes/gbt_c5a_gripper_link4_visuals_link4_mesh.obj" scale="1. 1. 1."/>
      </geometry>
    </visual>
    <visual>
      <origin xyz="-0. -0. 0." rpy="0. 0. 0."/>
      <geometry>
        <mesh filename="/home/gbt/isaacsim5.0/meshes/gbt_c5a_gripper_link4_collisions_link4_mesh.obj" scale="1. 1. 1."/>
      </geometry>
    </visual>
    <collision>
      <origin xyz="-0. -0. 0." rpy="0. 0. 0."/>
      <geometry>
        <mesh filename="/home/gbt/isaacsim5.0/meshes/gbt_c5a_gripper_link4_collisions_link4_mesh.obj" scale="1. 1. 1."/>
      </geometry>
    </collision>
  </link>
  <link name="gbt_c5a_gripper_link5">
    <inertial>
      <origin xyz="-0.000539 -0.018034 -0.003263" rpy="0. 0. 0."/>
      <mass value="1.823601"/>
      <inertia ixx="0.003117" ixy="-0.000019" ixz="-0.000008" iyy="0.0159" iyz="-0.000099" izz="0.003001"/>
    </inertial>
    <visual>
      <origin xyz="0. 0. -0." rpy="-0. 0. 0."/>
      <geometry>
        <mesh filename="/home/gbt/isaacsim5.0/meshes/gbt_c5a_gripper_link5_visuals_link5_mesh.obj" scale="1. 1. 1."/>
      </geometry>
    </visual>
    <visual>
      <origin xyz="0. 0. -0." rpy="-0. 0. 0."/>
      <geometry>
        <mesh filename="/home/gbt/isaacsim5.0/meshes/gbt_c5a_gripper_link5_collisions_link5_mesh.obj" scale="1. 1. 1."/>
      </geometry>
    </visual>
    <collision>
      <origin xyz="0. 0. -0." rpy="-0. 0. 0."/>
      <geometry>
        <mesh filename="/home/gbt/isaacsim5.0/meshes/gbt_c5a_gripper_link5_collisions_link5_mesh.obj" scale="1. 1. 1."/>
      </geometry>
    </collision>
  </link>
  <link name="gbt_c5a_gripper_link6">
    <inertial>
      <origin xyz="-0.000012 -0.000333 -0.014577" rpy="0. 0. 0."/>
      <mass value="0.240531"/>
      <inertia ixx="0.000135" ixy="0." ixz="0." iyy="0.000132" iyz="0." izz="0.000234"/>
    </inertial>
    <visual>
      <origin xyz="0. 0. 0." rpy="-0.0000002 0. 0. "/>
      <geometry>
        <mesh filename="/home/gbt/isaacsim5.0/meshes/gbt_c5a_gripper_link6_visuals_link6_mesh.obj" scale="1. 1. 1."/>
      </geometry>
    </visual>
    <visual>
      <origin xyz="0. 0. 0." rpy="-0.0000002 0. 0. "/>
      <geometry>
        <mesh filename="/home/gbt/isaacsim5.0/meshes/gbt_c5a_gripper_link6_collisions_link6_mesh.obj" scale="1. 1. 1."/>
      </geometry>
    </visual>
    <collision>
      <origin xyz="0. 0. 0." rpy="-0.0000002 0. 0. "/>
      <geometry>
        <mesh filename="/home/gbt/isaacsim5.0/meshes/gbt_c5a_gripper_link6_collisions_link6_mesh.obj" scale="1. 1. 1."/>
      </geometry>
    </collision>
  </link>
  <link name="left_inner_finger">
    <inertial>
      <origin xyz="0.0003 0.0160078 -0.0136946" rpy="0. 0. 0."/>
      <mass value="0.0104003"/>
      <inertia ixx="0.0000027" ixy="0." ixz="0." iyy="0.0000008" iyz="0.0000007" izz="0.0000023"/>
    </inertial>
    <visual>
      <origin xyz="0. -0. 0." rpy="-0. 0. 0."/>
      <geometry>
        <mesh filename="/home/gbt/isaacsim5.0/meshes/left_inner_finger_visuals_robotiq_arg2f_140_inner_finger_mesh.obj" scale="1. 1. 1."/>
      </geometry>
    </visual>
    <visual>
      <origin xyz="0. 0.0457554 -0.0272203" rpy="-0. 0. 0."/>
      <geometry>
        <box size="0.027 0.065 0.0075"/>
      </geometry>
    </visual>
    <visual>
      <origin xyz="0. -0. 0." rpy="-0. 0. 0."/>
      <geometry>
        <mesh filename="/home/gbt/isaacsim5.0/meshes/left_inner_finger_collisions_robotiq_arg2f_140_inner_finger_mesh.obj" scale="1. 1. 1."/>
      </geometry>
    </visual>
    <visual>
      <origin xyz="0. 0.0457554 -0.0272203" rpy="-0. 0. 0."/>
      <geometry>
        <box size="0.03 0.07 0.0075"/>
      </geometry>
    </visual>
    <collision>
      <origin xyz="0. -0. 0." rpy="-0. 0. 0."/>
      <geometry>
        <mesh filename="/home/gbt/isaacsim5.0/meshes/left_inner_finger_collisions_robotiq_arg2f_140_inner_finger_mesh.obj" scale="1. 1. 1."/>
      </geometry>
    </collision>
    <collision>
      <origin xyz="0. 0.0457554 -0.0272203" rpy="-0. 0. 0."/>
      <geometry>
        <box size="0.03 0.07 0.0075"/>
      </geometry>
    </collision>
  </link>
  <link name="left_inner_knuckle">
    <inertial>
      <origin xyz="0.000123 0.0507851 0.0010397" rpy="0. 0. 0."/>
      <mass value="0.0271177"/>
      <inertia ixx="0.0000262" ixy="-0.0000002" ixz="-0." iyy="0.0000028" iyz="-0.0000005" izz="0.0000284"/>
    </inertial>
    <visual>
      <origin xyz="0. 0. 0." rpy="-0. 0. 0."/>
      <geometry>
        <mesh filename="/home/gbt/isaacsim5.0/meshes/left_inner_knuckle_visuals_robotiq_arg2f_140_inner_knuckle_mesh.obj" scale="1. 1. 1."/>
      </geometry>
    </visual>
    <visual>
      <origin xyz="0. 0. 0." rpy="-0. 0. 0."/>
      <geometry>
        <mesh filename="/home/gbt/isaacsim5.0/meshes/left_inner_knuckle_collisions_robotiq_arg2f_140_inner_knuckle_mesh.obj" scale="1. 1. 1."/>
      </geometry>
    </visual>
    <collision>
      <origin xyz="0. 0. 0." rpy="-0. 0. 0."/>
      <geometry>
        <mesh filename="/home/gbt/isaacsim5.0/meshes/left_inner_knuckle_collisions_robotiq_arg2f_140_inner_knuckle_mesh.obj" scale="1. 1. 1."/>
      </geometry>
    </collision>
  </link>
  <link name="left_outer_knuckle">
    <inertial>
      <origin xyz="0.0001639 0.0458404 0.0117804" rpy="0. 0. 0."/>
      <mass value="0.0311462"/>
      <inertia ixx="0.0000296" ixy="-0.0000001" ixz="0.0000001" iyy="0.0000116" iyz="0.0000109" izz="0.0000208"/>
    </inertial>
    <visual>
      <origin xyz="0. 0. 0." rpy="-0. 0. 3.1415927"/>
      <geometry>
        <mesh filename="/home/gbt/isaacsim5.0/meshes/left_outer_knuckle_visuals_robotiq_arg2f_140_outer_knuckle_mesh.obj" scale="1. 1. 1."/>
      </geometry>
    </visual>
    <visual>
      <origin xyz="0. -0.01822 0.0260018" rpy="-0. 0. 3.1415927"/>
      <geometry>
        <mesh filename="/home/gbt/isaacsim5.0/meshes/left_outer_knuckle_visuals_robotiq_arg2f_140_outer_finger_mesh.obj" scale="1. 1. 1."/>
      </geometry>
    </visual>
    <visual>
      <origin xyz="0. 0. 0." rpy="-0. 0. 3.1415927"/>
      <geometry>
        <mesh filename="/home/gbt/isaacsim5.0/meshes/left_outer_knuckle_collisions_robotiq_arg2f_140_outer_knuckle_mesh.obj" scale="1. 1. 1."/>
      </geometry>
    </visual>
    <visual>
      <origin xyz="0. -0.01822 0.0260018" rpy="-0. 0. 3.1415927"/>
      <geometry>
        <mesh filename="/home/gbt/isaacsim5.0/meshes/left_outer_knuckle_collisions_robotiq_arg2f_140_outer_finger_mesh.obj" scale="1. 1. 1."/>
      </geometry>
    </visual>
    <collision>
      <origin xyz="0. 0. 0." rpy="-0. 0. 3.1415927"/>
      <geometry>
        <mesh filename="/home/gbt/isaacsim5.0/meshes/left_outer_knuckle_collisions_robotiq_arg2f_140_outer_knuckle_mesh.obj" scale="1. 1. 1."/>
      </geometry>
    </collision>
    <collision>
      <origin xyz="0. -0.01822 0.0260018" rpy="-0. 0. 3.1415927"/>
      <geometry>
        <mesh filename="/home/gbt/isaacsim5.0/meshes/left_outer_knuckle_collisions_robotiq_arg2f_140_outer_finger_mesh.obj" scale="1. 1. 1."/>
      </geometry>
    </collision>
  </link>
  <link name="right_inner_finger">
    <inertial>
      <origin xyz="0.0003 0.0160078 -0.0136946" rpy="0. 0. 0."/>
      <mass value="0.0104003"/>
      <inertia ixx="0.0000027" ixy="0." ixz="0." iyy="0.0000008" iyz="0.0000007" izz="0.0000023"/>
    </inertial>
    <visual>
      <origin xyz="0. 0. 0." rpy="0. 0. 0."/>
      <geometry>
        <mesh filename="/home/gbt/isaacsim5.0/meshes/right_inner_finger_visuals_robotiq_arg2f_140_inner_finger_mesh.obj" scale="1. 1. 1."/>
      </geometry>
    </visual>
    <visual>
      <origin xyz="0. 0.0457554 -0.0272203" rpy="0. 0. 0."/>
      <geometry>
        <box size="0.027 0.065 0.0075"/>
      </geometry>
    </visual>
    <visual>
      <origin xyz="0. 0. 0." rpy="0. 0. 0."/>
      <geometry>
        <mesh filename="/home/gbt/isaacsim5.0/meshes/right_inner_finger_collisions_robotiq_arg2f_140_inner_finger_mesh.obj" scale="1. 1. 1."/>
      </geometry>
    </visual>
    <visual>
      <origin xyz="0. 0.0457554 -0.0272203" rpy="0. 0. 0."/>
      <geometry>
        <box size="0.03 0.07 0.0075"/>
      </geometry>
    </visual>
    <collision>
      <origin xyz="0. 0. 0." rpy="0. 0. 0."/>
      <geometry>
        <mesh filename="/home/gbt/isaacsim5.0/meshes/right_inner_finger_collisions_robotiq_arg2f_140_inner_finger_mesh.obj" scale="1. 1. 1."/>
      </geometry>
    </collision>
    <collision>
      <origin xyz="0. 0.0457554 -0.0272203" rpy="0. 0. 0."/>
      <geometry>
        <box size="0.03 0.07 0.0075"/>
      </geometry>
    </collision>
  </link>
  <link name="right_inner_knuckle">
    <inertial>
      <origin xyz="0.000123 0.0507851 0.0010397" rpy="0. 0. 0."/>
      <mass value="0.0271177"/>
      <inertia ixx="0.0000262" ixy="-0.0000002" ixz="-0." iyy="0.0000028" iyz="-0.0000005" izz="0.0000284"/>
    </inertial>
    <visual>
      <origin xyz="0. 0. 0." rpy="0. 0. 0."/>
      <geometry>
        <mesh filename="/home/gbt/isaacsim5.0/meshes/right_inner_knuckle_visuals_robotiq_arg2f_140_inner_knuckle_mesh.obj" scale="1. 1. 1."/>
      </geometry>
    </visual>
    <visual>
      <origin xyz="0. 0. 0." rpy="0. 0. 0."/>
      <geometry>
        <mesh filename="/home/gbt/isaacsim5.0/meshes/right_inner_knuckle_collisions_robotiq_arg2f_140_inner_knuckle_mesh.obj" scale="1. 1. 1."/>
      </geometry>
    </visual>
    <collision>
      <origin xyz="0. 0. 0." rpy="0. 0. 0."/>
      <geometry>
        <mesh filename="/home/gbt/isaacsim5.0/meshes/right_inner_knuckle_collisions_robotiq_arg2f_140_inner_knuckle_mesh.obj" scale="1. 1. 1."/>
      </geometry>
    </collision>
  </link>
  <link name="right_outer_knuckle">
    <inertial>
      <origin xyz="0.0001639 0.0458404 0.0117804" rpy="0. 0. 0."/>
      <mass value="0.0311462"/>
      <inertia ixx="0.0000296" ixy="-0.0000001" ixz="0.0000001" iyy="0.0000116" iyz="0.0000109" izz="0.0000208"/>
    </inertial>
    <visual>
      <origin xyz="0. 0. 0." rpy="0. 0. 0."/>
      <geometry>
        <mesh filename="/home/gbt/isaacsim5.0/meshes/right_outer_knuckle_visuals_robotiq_arg2f_140_outer_knuckle_mesh.obj" scale="1. 1. 1."/>
      </geometry>
    </visual>
    <visual>
      <origin xyz="0. 0.01822 0.0260018" rpy="0. 0. 0."/>
      <geometry>
        <mesh filename="/home/gbt/isaacsim5.0/meshes/right_outer_knuckle_visuals_robotiq_arg2f_140_outer_finger_mesh.obj" scale="1. 1. 1."/>
      </geometry>
    </visual>
    <visual>
      <origin xyz="0. 0. 0." rpy="0. 0. 0."/>
      <geometry>
        <mesh filename="/home/gbt/isaacsim5.0/meshes/right_outer_knuckle_collisions_robotiq_arg2f_140_outer_knuckle_mesh.obj" scale="1. 1. 1."/>
      </geometry>
    </visual>
    <visual>
      <origin xyz="0. 0.01822 0.0260018" rpy="0. 0. 0."/>
      <geometry>
        <mesh filename="/home/gbt/isaacsim5.0/meshes/right_outer_knuckle_collisions_robotiq_arg2f_140_outer_finger_mesh.obj" scale="1. 1. 1."/>
      </geometry>
    </visual>
    <collision>
      <origin xyz="0. 0. 0." rpy="0. 0. 0."/>
      <geometry>
        <mesh filename="/home/gbt/isaacsim5.0/meshes/right_outer_knuckle_collisions_robotiq_arg2f_140_outer_knuckle_mesh.obj" scale="1. 1. 1."/>
      </geometry>
    </collision>
    <collision>
      <origin xyz="0. 0.01822 0.0260018" rpy="0. 0. 0."/>
      <geometry>
        <mesh filename="/home/gbt/isaacsim5.0/meshes/right_outer_knuckle_collisions_robotiq_arg2f_140_outer_finger_mesh.obj" scale="1. 1. 1."/>
      </geometry>
    </collision>
  </link>
</robot>
