<?xml version="1.0"?>
<robot name="GBT_C7A" xmlns:xacro="http://www.ros.org/wiki/xacro">

  <!-- Base Link: base_link -->
  <link name="base_link">
  <inertial>
      <origin
        xyz="-5.26704954492915E-06 -0.0098126576895962 0.0491108287185979"
        rpy="0 0 0" />
      <mass
        value="9.16040326523465" />
      <inertia
        ixx="0.0419458054611511"
        ixy="1.03351238796275E-05"
        ixz="-1.16385212137257E-06"
        iyy="0.0160795355795088"
        iyz="-0.00415210835016869"
        izz="0.0465550656362786" />
    </inertial>
    <visual>
      <origin xyz="0 0 0" rpy="0 0 0"/>
      <geometry>
        <mesh filename="../meshes/visual/base_link.obj" scale="0.001 0.001 0.001"/>
      </geometry>
    </visual>
    <collision>
      <origin xyz="0 0 0" rpy="0 0 0"/>
      <geometry>
        <mesh filename="../meshes/collision/base_link.stl" scale="0.001 0.001 0.001"/>
      </geometry>
    </collision>
  </link>

  <!-- link1 -->
  <joint name="joint1" type="revolute">
    <parent link="base_link"/>
    <child link="link1"/>
    <origin xyz="0 0 0.178" rpy="0 0 0"/>
    <axis xyz="0 0 1"/>
    <limit effort="100" lower="-6.283185307179" upper="6.283185307179" velocity="1"/>
  </joint>
  <link name="link1">
    <inertial>
      <origin
        xyz="-2.2231E-07 0.0039863 0.082573"
        rpy="0 0 0" />
      <mass
        value="15.175" />
      <inertia
        ixx="0.047239"
        ixy="-1.1092E-08"
        ixz="6.1658E-07"
        iyy="0.045942"
        iyz="-0.00010066"
        izz="0.029088" />
    </inertial>
    <visual>
      <origin xyz="0 0 0" rpy="0 0 0"/>
      <geometry>
        <mesh filename="../meshes/visual/link1.obj" scale="0.001 0.001 0.001"/>
      </geometry>
    </visual>
    <collision>
      <origin xyz="0 0 0" rpy="0 0 0"/>
      <geometry>
        <mesh filename="../meshes/collision/link1.stl" scale="0.001 0.001 0.001"/>
      </geometry>
    </collision>
  </link>

  <!-- link2 -->
  <joint name="joint2" type="revolute">
    <parent link="link1"/>
    <child link="link2"/>
    <origin xyz="0 0.147 0" rpy="1.5707963267948966 0 0"/>
    <axis xyz="0 0 1"/>
    <limit effort="100" lower="-1.483529864195" upper="4.625122517784" velocity="1"/>
  </joint>
  <link name="link2">
    <inertial>
      <origin
        xyz="0.175 -2.4749E-07 0.082978"
        rpy="0 0 0" />
      <mass
        value="42.406" />
      <inertia
        ixx="0.10612"
        ixy="2.7254E-06"
        ixz="1.9039E-06"
        iyy="1.0509"
        iyz="8.5915E-07"
        izz="1.0146" />
    </inertial>
    <visual>
      <origin xyz="0 0 0" rpy="0 0 0"/>
      <geometry>
        <mesh filename="../meshes/visual/link2.obj" scale="0.001 0.001 0.001"/>
      </geometry>
    </visual>
    <collision>
      <origin xyz="0 0 0" rpy="0 0 0"/>
      <geometry>
        <mesh filename="../meshes/collision/link2.stl" scale="0.001 0.001 0.001"/>
      </geometry>
    </collision>
  </link>

  <!-- link3 -->
  <joint name="joint3" type="revolute">
    <parent link="link2"/>
    <child link="link3"/>
    <origin xyz="0.350 0 0.147" rpy="0 0 0"/>
    <axis xyz="0 0 1"/>
    <limit effort="100" lower="-2.879793265790" upper="2.879793265790" velocity="1"/>
  </joint>
  <link name="link3">
    <inertial>
      <origin
        xyz="-0.14241 6.1389E-07 0.056555"
        rpy="0 0 0" />
      <mass
        value="22.494" />
      <inertia
        ixx="0.03219"
        ixy="-6.2382E-08"
        ixz="0.014535"
        iyy="0.36351"
        iyz="6.3874E-08"
        izz="0.35645" />
    </inertial>
    <visual>
      <origin xyz="0 0 0" rpy="0 0 0"/>
      <geometry>
        <mesh filename="../meshes/visual/link3.obj" scale="0.001 0.001 0.001"/>
      </geometry>
    </visual>
    <collision>
      <origin xyz="0 0 0" rpy="0 0 0"/>
      <geometry>
        <mesh filename="../meshes/collision/link3.stl" scale="0.001 0.001 0.001"/>
      </geometry>
    </collision>
  </link>

  <!-- link4 -->
  <joint name="joint4" type="revolute">
    <parent link="link3"/>
    <child link="link4"/>
    <origin xyz="0.3117 0 -0.1233" rpy="0 0 0"/>
    <axis xyz="0 0 1"/>
    <limit effort="100" lower="-1.483529864195" upper="4.625122517784" velocity="1"/>
  </joint>
  <link name="link4">
    <inertial>
      <origin
        xyz="1.2977E-07 0.0036933 0.046819"
        rpy="0 0 0" />
      <mass
        value="5.9624" />
      <inertia
        ixx="0.01117"
        ixy="8.492E-08"
        ixz="1.0592E-08"
        iyy="0.0057359"
        iyz="-0.00011927"
        izz="0.010395" />
    </inertial>
    <visual>
      <origin xyz="0 0 0" rpy="0 0 0"/>
      <geometry>
        <mesh filename="../meshes/visual/link4.obj" scale="0.001 0.001 0.001"/>
      </geometry>
    </visual>
    <collision>
      <origin xyz="0 0 0" rpy="0 0 0"/>
      <geometry>
        <mesh filename="../meshes/collision/link4.stl" scale="0.001 0.001 0.001"/>
      </geometry>
    </collision>
  </link>

  <!-- link5 -->
  <joint name="joint5" type="revolute">
    <parent link="link4"/>
    <child link="link5"/>
    <origin xyz="0 -0.1233 0" rpy="1.5707963267948966 0 0"/>
    <axis xyz="0 0 1"/>
    <limit effort="100" lower="-6.283185307179" upper="6.283185307179" velocity="1"/>
  </joint>
  <link name="link5">
    <inertial>
      <origin
        xyz="1.3304E-07 -0.00083634 -0.04715"
        rpy="0 0 0" />
      <mass
        value="6.3691" />
      <inertia
        ixx="0.013244"
        ixy="1.0431E-07"
        ixz="3.2379E-08"
        iyy="0.0060649"
        iyz="-1.9476E-05"
        izz="0.012458" />
    </inertial>
    <visual>
      <origin xyz="0 0 0" rpy="0 0 0"/>
      <geometry>
        <mesh filename="../meshes/visual/link5.obj" scale="0.001 0.001 0.001"/>
      </geometry>
    </visual>
    <collision>
      <origin xyz="0 0 0" rpy="0 0 0"/>
      <geometry>
        <mesh filename="../meshes/collision/link5.stl" scale="0.001 0.001 0.001"/>
      </geometry>
    </collision>
  </link>

  <!-- link6 -->
  <joint name="joint6" type="revolute">
    <parent link="link5"/>
    <child link="link6"/>
    <origin xyz="0 -0.1003 0" rpy="1.5707963267948966 0 0"/>
    <axis xyz="0 0 1"/>
    <limit effort="100" lower="-6.283185307179" upper="6.283185307179" velocity="1"/>
  </joint>
  <link name="link6">
    <inertial>
      <origin
        xyz="3.8813E-08 0.00017432 0.012497"
        rpy="0 0 0" />
      <mass
        value="1.0139" />
      <inertia
        ixx="0.00046196"
        ixy="1.8319E-11"
        ixz="-3.9805E-12"
        iyy="0.00046763"
        iyz="-6.4994E-08"
        izz="0.00080288" />
    </inertial>
    <visual>
      <origin xyz="0 0 0" rpy="0 0 0"/>
      <geometry>
        <mesh filename="../meshes/visual/link6.obj" scale="0.001 0.001 0.001"/>
      </geometry>
    </visual>
    <collision>
      <origin xyz="0 0 0" rpy="0 0 0"/>
      <geometry>
        <mesh filename="../meshes/collision/link6.stl" scale="0.001 0.001 0.001"/>
      </geometry>
    </collision>
  </link>

</robot>
