<?xml version="1.0"?>
<robot name="GBT_C7A" xmlns:xacro="http://www.ros.org/wiki/xacro">

  <!-- Base Link: ARM1 -->
  <link name="ARM1">
  <inertial>
      <origin
        xyz="-5.26704954492915E-06 -0.0098126576895962 0.0491108287185979"
        rpy="0 0 0" />
      <mass
        value="9.16040326523465" />
      <inertia
        ixx="0.0419458054611511"
        ixy="1.03351238796275E-05"
        ixz="-1.16385212137257E-06"
        iyy="0.0160795355795088"
        iyz="-0.00415210835016869"
        izz="0.0465550656362786" />
    </inertial>
    <visual>
      <origin xyz="0 0 0" rpy="0 0 0"/>
      <geometry>
        <mesh filename="package://gbt_gripper_description/meshes/visual/ARM1.obj" scale="0.001 0.001 0.001"/>
      </geometry>
    </visual>
    <collision>
      <origin xyz="0 0 0" rpy="0 0 0"/>
      <geometry>
        <mesh filename="package://gbt_gripper_description/meshes/collision/ARM1.stl" scale="0.001 0.001 0.001"/>
      </geometry>
    </collision>
  </link>

  <!-- ARM2 -->
  <joint name="joint_1_2" type="revolute">
    <parent link="ARM1"/>
    <child link="ARM2"/>
    <origin xyz="0 0 0.178" rpy="0 0 0"/>
    <axis xyz="0 0 1"/>
    <limit effort="100" lower="-6.283185307179" upper="6.283185307179" velocity="6.28"/>
  </joint>
  <link name="ARM2">
    <inertial>
      <origin
        xyz="-2.2231E-07 0.0039863 0.082573"
        rpy="0 0 0" />
      <mass
        value="15.175" />
      <inertia
        ixx="0.047239"
        ixy="-1.1092E-08"
        ixz="6.1658E-07"
        iyy="0.045942"
        iyz="-0.00010066"
        izz="0.029088" />
    </inertial>
    <visual>
      <origin xyz="0 0 0" rpy="0 0 0"/>
      <geometry>
        <mesh filename="package://gbt_gripper_description/meshes/visual/ARM2.obj" scale="0.001 0.001 0.001"/>
      </geometry>
    </visual>
    <collision>
      <origin xyz="0 0 0" rpy="0 0 0"/>
      <geometry>
        <mesh filename="package://gbt_gripper_description/meshes/collision/ARM2.stl" scale="0.001 0.001 0.001"/>
      </geometry>
    </collision>
  </link>

  <!-- ARM3 -->
  <joint name="joint_2_3" type="revolute">
    <parent link="ARM2"/>
    <child link="ARM3"/>
    <origin xyz="0 0.147 0" rpy="1.5707963267948966 0 0"/>
    <axis xyz="0 0 1"/>
    <limit effort="100" lower="-1.483529864195" upper="4.625122517784" velocity="6.28"/>
  </joint>
  <link name="ARM3">
    <inertial>
      <origin
        xyz="0.175 -2.4749E-07 0.082978"
        rpy="0 0 0" />
      <mass
        value="42.406" />
      <inertia
        ixx="0.10612"
        ixy="2.7254E-06"
        ixz="1.9039E-06"
        iyy="1.0509"
        iyz="8.5915E-07"
        izz="1.0146" />
    </inertial>
    <visual>
      <origin xyz="0 0 0" rpy="0 0 0"/>
      <geometry>
        <mesh filename="package://gbt_gripper_description/meshes/visual/ARM3.obj" scale="0.001 0.001 0.001"/>
      </geometry>
    </visual>
    <collision>
      <origin xyz="0 0 0" rpy="0 0 0"/>
      <geometry>
        <mesh filename="package://gbt_gripper_description/meshes/collision/ARM3.stl" scale="0.001 0.001 0.001"/>
      </geometry>
    </collision>
  </link>

  <!-- ARM4 -->
  <joint name="joint_3_4" type="revolute">
    <parent link="ARM3"/>
    <child link="ARM4"/>
    <origin xyz="0.350 0 0.147" rpy="0 0 0"/>
    <axis xyz="0 0 1"/>
    <limit effort="100" lower="-2.879793265790" upper="2.879793265790" velocity="6.28"/>
  </joint>
  <link name="ARM4">
    <inertial>
      <origin
        xyz="-0.14241 6.1389E-07 0.056555"
        rpy="0 0 0" />
      <mass
        value="22.494" />
      <inertia
        ixx="0.03219"
        ixy="-6.2382E-08"
        ixz="0.014535"
        iyy="0.36351"
        iyz="6.3874E-08"
        izz="0.35645" />
    </inertial>
    <visual>
      <origin xyz="0 0 0" rpy="0 0 0"/>
      <geometry>
        <mesh filename="package://gbt_gripper_description/meshes/visual/ARM4.obj" scale="0.001 0.001 0.001"/>
      </geometry>
    </visual>
    <collision>
      <origin xyz="0 0 0" rpy="0 0 0"/>
      <geometry>
        <mesh filename="package://gbt_gripper_description/meshes/collision/ARM4.stl" scale="0.001 0.001 0.001"/>
      </geometry>
    </collision>
  </link>

  <!-- ARM5 -->
  <joint name="joint_4_5" type="revolute">
    <parent link="ARM4"/>
    <child link="ARM5"/>
    <origin xyz="0.3117 0 -0.1233" rpy="0 0 0"/>
    <axis xyz="0 0 1"/>
    <limit effort="100" lower="-1.483529864195" upper="4.625122517784" velocity="6.28"/>
  </joint>
  <link name="ARM5">
    <inertial>
      <origin
        xyz="1.2977E-07 0.0036933 0.046819"
        rpy="0 0 0" />
      <mass
        value="5.9624" />
      <inertia
        ixx="0.01117"
        ixy="8.492E-08"
        ixz="1.0592E-08"
        iyy="0.0057359"
        iyz="-0.00011927"
        izz="0.010395" />
    </inertial>
    <visual>
      <origin xyz="0 0 0" rpy="0 0 0"/>
      <geometry>
        <mesh filename="package://gbt_gripper_description/meshes/visual/ARM5.obj" scale="0.001 0.001 0.001"/>
      </geometry>
    </visual>
    <collision>
      <origin xyz="0 0 0" rpy="0 0 0"/>
      <geometry>
        <mesh filename="package://gbt_gripper_description/meshes/collision/ARM5.stl" scale="0.001 0.001 0.001"/>
      </geometry>
    </collision>
  </link>

  <!-- ARM6 -->
  <joint name="joint_5_6" type="revolute">
    <parent link="ARM5"/>
    <child link="ARM6"/>
    <origin xyz="0 -0.1233 0" rpy="1.5707963267948966 0 0"/>
    <axis xyz="0 0 1"/>
    <limit effort="100" lower="-6.283185307179" upper="6.283185307179" velocity="6.28"/>
  </joint>
  <link name="ARM6">
    <inertial>
      <origin
        xyz="1.3304E-07 -0.00083634 -0.04715"
        rpy="0 0 0" />
      <mass
        value="6.3691" />
      <inertia
        ixx="0.013244"
        ixy="1.0431E-07"
        ixz="3.2379E-08"
        iyy="0.0060649"
        iyz="-1.9476E-05"
        izz="0.012458" />
    </inertial>
    <visual>
      <origin xyz="0 0 0" rpy="0 0 0"/>
      <geometry>
        <mesh filename="package://gbt_gripper_description/meshes/visual/ARM6.obj" scale="0.001 0.001 0.001"/>
      </geometry>
    </visual>
    <collision>
      <origin xyz="0 0 0" rpy="0 0 0"/>
      <geometry>
        <mesh filename="package://gbt_gripper_description/meshes/collision/ARM6.stl" scale="0.001 0.001 0.001"/>
      </geometry>
    </collision>
  </link>

  <!-- ARM7 -->
  <joint name="joint_6_7" type="revolute">
    <parent link="ARM6"/>
    <child link="ARM7"/>
    <origin xyz="0 -0.1003 0" rpy="1.5707963267948966 0 0"/>
    <axis xyz="0 0 1"/>
    <limit effort="100" lower="-6.283185307179" upper="6.283185307179" velocity="6.28"/>
  </joint>
  <link name="ARM7">
    <inertial>
      <origin
        xyz="3.8813E-08 0.00017432 0.012497"
        rpy="0 0 0" />
      <mass
        value="1.0139" />
      <inertia
        ixx="0.00046196"
        ixy="1.8319E-11"
        ixz="-3.9805E-12"
        iyy="0.00046763"
        iyz="-6.4994E-08"
        izz="0.00080288" />
    </inertial>
    <visual>
      <origin xyz="0 0 0" rpy="0 0 0"/>
      <geometry>
        <mesh filename="package://gbt_gripper_description/meshes/visual/ARM7.obj" scale="0.001 0.001 0.001"/>
      </geometry>
    </visual>
    <collision>
      <origin xyz="0 0 0" rpy="0 0 0"/>
      <geometry>
        <mesh filename="package://gbt_gripper_description/meshes/collision/ARM7.stl" scale="0.001 0.001 0.001"/>
      </geometry>
    </collision>
  </link>

  <!-- gripper -->
  <link name="robotiq_arg2f_base_link">
    <inertial>
      <origin rpy="0 0 0" xyz="8.625E-08 -4.6583E-06 0.03145"/>
      <mass value="0.22652"/>
      <inertia ixx="0.00020005" ixy="-4.2442E-10" ixz="-2.9069E-10" iyy="0.00017832" iyz="-3.4402E-08" izz="0.00013478"/>
    </inertial>
    <visual>
      <origin rpy="0 0 0" xyz="0 0 0"/>
      <geometry>
        <mesh filename="package://gbt_gripper_description/meshes/visual/robotiq_arg2f_base_link.stl"/>
      </geometry>
      <material name="">
        <color rgba="0.1 0.1 0.1 1"/>
      </material>
    </visual>
    <collision>
      <origin rpy="0 0 0" xyz="0 0 0"/>
      <geometry>
        <mesh filename="package://gbt_gripper_description/meshes/collision/robotiq_arg2f_base_link.stl"/>
      </geometry>
    </collision>
  </link>
  <link name="left_outer_knuckle">
    <inertial>
      <origin rpy="0 0 0" xyz="-0.000200000000003065 0.0199435877845359 0.0292245259211331"/>
      <mass value="0.00853198276973456"/>
      <inertia ixx="2.89328108496468E-06" ixy="-1.57935047237397E-19" ixz="-1.93980378593255E-19" iyy="1.86719750325683E-06" iyz="-1.21858577871576E-06" izz="1.21905238907251E-06"/>
    </inertial>
    <visual>
      <origin rpy="0 0 0" xyz="0 0 0"/>
      <geometry>
        <mesh filename="package://gbt_gripper_description/meshes/visual/robotiq_arg2f_140_outer_knuckle.stl"/>
      </geometry>
      <material name="">
        <color rgba="0.792156862745098 0.819607843137255 0.933333333333333 1"/>
      </material>
    </visual>
    <collision>
      <origin rpy="0 0 0" xyz="0 0 0"/>
      <geometry>
        <mesh filename="package://gbt_gripper_description/meshes/collision/robotiq_arg2f_140_outer_knuckle.stl"/>
      </geometry>
    </collision>
  </link>
  <link name="left_outer_finger">
    <inertial>
      <origin rpy="0 0 0" xyz="0.00030115855001899 0.0373907951953854 -0.0208027427000385"/>
      <mass value="0.022614240507152"/>
      <inertia ixx="1.52518312458174E-05" ixy="9.76583423954399E-10" ixz="-5.43838577022588E-10" iyy="6.17694243867776E-06" iyz="6.78636130740228E-06" izz="1.16494917907219E-05"/>
    </inertial>
    <visual>
      <origin rpy="0 0 0" xyz="0 0 0"/>
      <geometry>
        <mesh filename="package://gbt_gripper_description/meshes/visual/robotiq_arg2f_140_outer_finger.stl"/>
      </geometry>
      <material name="">
        <color rgba="0.1 0.1 0.1 1"/>
      </material>
    </visual>
    <collision>
      <origin rpy="0 0 0" xyz="0 0 0"/>
      <geometry>
        <mesh filename="package://gbt_gripper_description/meshes/collision/robotiq_arg2f_140_outer_finger.stl"/>
      </geometry>
    </collision>
  </link>
  <link name="left_inner_finger">
    <inertial>
      <origin rpy="0 0 0" xyz="0.000299999999999317 0.0160078233491243 -0.0136945669206257"/>
      <mass value="0.0104003125914103"/>
      <inertia ixx="2.71909453810972E-06" ixy="1.35402465472579E-21" ixz="-7.1817349065269E-22" iyy="7.69100314106116E-07" iyz="6.74715432769696E-07" izz="2.30315190420171E-06"/>
    </inertial>
    <visual>
      <origin rpy="0 0 0" xyz="0 0 0"/>
      <geometry>
        <mesh filename="package://gbt_gripper_description/meshes/visual/robotiq_arg2f_140_inner_finger.stl"/>
      </geometry>
      <material name="">
        <color rgba="0.1 0.1 0.1 1"/>
      </material>
    </visual>
    <collision>
      <origin rpy="0 0 0" xyz="0 0 0"/>
      <geometry>
        <mesh filename="package://gbt_gripper_description/meshes/collision/robotiq_arg2f_140_inner_finger.stl"/>
      </geometry>
    </collision>
  </link>
  <link name="left_inner_finger_pad">
    <visual>
      <origin rpy="0 0 0" xyz="0 0 0"/>
      <geometry>
        <box size="0.027 0.065 0.0075"/>
      </geometry>
      <material name="">
        <color rgba="0.9 0.9 0.9 1"/>
      </material>
    </visual>
    <collision>
      <origin rpy="0 0 0" xyz="0 0 0"/>
      <geometry>
        <box size="0.03 0.07 0.0075"/>
      </geometry>
      <material name="">
        <color rgba="0.9 0.0 0.0 1"/>
      </material>
    </collision>
  </link>
  <link name="left_inner_knuckle">
    <inertial>
      <origin rpy="0 0 0" xyz="0.000123011831763771 0.0507850843201817 0.00103968640075166"/>
      <mass value="0.0271177346495152"/>
      <inertia ixx="2.61910379223783E-05" ixy="-2.43616858946494E-07" ixz="-6.37789906117123E-09" iyy="2.8270243746167E-06" iyz="-5.37200748039765E-07" izz="2.83695868220296E-05"/>
    </inertial>
    <visual>
      <origin rpy="0 0 0" xyz="0 0 0"/>
      <geometry>
        <mesh filename="package://gbt_gripper_description/meshes/visual/robotiq_arg2f_140_inner_knuckle.stl"/>
      </geometry>
      <material name="">
        <color rgba="0.1 0.1 0.1 1"/>
      </material>
    </visual>
    <collision>
      <origin rpy="0 0 0" xyz="0 0 0"/>
      <geometry>
        <mesh filename="package://gbt_gripper_description/meshes/collision/robotiq_arg2f_140_inner_knuckle.stl"/>
      </geometry>
    </collision>
  </link>
  <link name="right_outer_knuckle">
    <inertial>
      <origin rpy="0 0 0" xyz="-0.000200000000003065 0.0199435877845359 0.0292245259211331"/>
      <mass value="0.00853198276973456"/>
      <inertia ixx="2.89328108496468E-06" ixy="-1.57935047237397E-19" ixz="-1.93980378593255E-19" iyy="1.86719750325683E-06" iyz="-1.21858577871576E-06" izz="1.21905238907251E-06"/>
    </inertial>
    <visual>
      <origin rpy="0 0 0" xyz="0 0 0"/>
      <geometry>
        <mesh filename="package://gbt_gripper_description/meshes/visual/robotiq_arg2f_140_outer_knuckle.stl"/>
      </geometry>
      <material name="">
        <color rgba="0.792156862745098 0.819607843137255 0.933333333333333 1"/>
      </material>
    </visual>
    <collision>
      <origin rpy="0 0 0" xyz="0 0 0"/>
      <geometry>
        <mesh filename="package://gbt_gripper_description/meshes/collision/robotiq_arg2f_140_outer_knuckle.stl"/>
      </geometry>
    </collision>
  </link>
  <link name="right_outer_finger">
    <inertial>
      <origin rpy="0 0 0" xyz="0.00030115855001899 0.0373907951953854 -0.0208027427000385"/>
      <mass value="0.022614240507152"/>
      <inertia ixx="1.52518312458174E-05" ixy="9.76583423954399E-10" ixz="-5.43838577022588E-10" iyy="6.17694243867776E-06" iyz="6.78636130740228E-06" izz="1.16494917907219E-05"/>
    </inertial>
    <visual>
      <origin rpy="0 0 0" xyz="0 0 0"/>
      <geometry>
        <mesh filename="package://gbt_gripper_description/meshes/visual/robotiq_arg2f_140_outer_finger.stl"/>
      </geometry>
      <material name="">
        <color rgba="0.1 0.1 0.1 1"/>
      </material>
    </visual>
    <collision>
      <origin rpy="0 0 0" xyz="0 0 0"/>
      <geometry>
        <mesh filename="package://gbt_gripper_description/meshes/collision/robotiq_arg2f_140_outer_finger.stl"/>
      </geometry>
    </collision>
  </link>
  <link name="right_inner_finger">
    <inertial>
      <origin rpy="0 0 0" xyz="0.000299999999999317 0.0160078233491243 -0.0136945669206257"/>
      <mass value="0.0104003125914103"/>
      <inertia ixx="2.71909453810972E-06" ixy="1.35402465472579E-21" ixz="-7.1817349065269E-22" iyy="7.69100314106116E-07" iyz="6.74715432769696E-07" izz="2.30315190420171E-06"/>
    </inertial>
    <visual>
      <origin rpy="0 0 0" xyz="0 0 0"/>
      <geometry>
        <mesh filename="package://gbt_gripper_description/meshes/visual/robotiq_arg2f_140_inner_finger.stl"/>
      </geometry>
      <material name="">
        <color rgba="0.1 0.1 0.1 1"/>
      </material>
    </visual>
    <collision>
      <origin rpy="0 0 0" xyz="0 0 0"/>
      <geometry>
        <mesh filename="package://gbt_gripper_description/meshes/collision/robotiq_arg2f_140_inner_finger.stl"/>
      </geometry>
    </collision>
  </link>
  <link name="right_inner_finger_pad">
    <visual>
      <origin rpy="0 0 0" xyz="0 0 0"/>
      <geometry>
        <box size="0.027 0.065 0.0075"/>
      </geometry>
      <material name="">
        <color rgba="0.9 0.9 0.9 1"/>
      </material>
    </visual>
    <collision>
      <origin rpy="0 0 0" xyz="0 0 0"/>
      <geometry>
        <box size="0.03 0.07 0.0075"/>
      </geometry>
      <material name="">
        <color rgba="0.9 0.0 0.0 1"/>
      </material>
    </collision>
  </link>
  <link name="right_inner_knuckle">
    <inertial>
      <origin rpy="0 0 0" xyz="0.000123011831763771 0.0507850843201817 0.00103968640075166"/>
      <mass value="0.0271177346495152"/>
      <inertia ixx="2.61910379223783E-05" ixy="-2.43616858946494E-07" ixz="-6.37789906117123E-09" iyy="2.8270243746167E-06" iyz="-5.37200748039765E-07" izz="2.83695868220296E-05"/>
    </inertial>
    <visual>
      <origin rpy="0 0 0" xyz="0 0 0"/>
      <geometry>
        <mesh filename="package://gbt_gripper_description/meshes/visual/robotiq_arg2f_140_inner_knuckle.stl"/>
      </geometry>
      <material name="">
        <color rgba="0.1 0.1 0.1 1"/>
      </material>
    </visual>
    <collision>
      <origin rpy="0 0 0" xyz="0 0 0"/>
      <geometry>
        <mesh filename="package://gbt_gripper_description/meshes/collision/robotiq_arg2f_140_inner_knuckle.stl"/>
      </geometry>
    </collision>
  </link>
  <joint name="finger_joint" type="revolute">
    <origin rpy="2.2957963267948966 0 0" xyz="0 -0.030601 0.054905"/>
    <parent link="robotiq_arg2f_base_link"/>
    <child link="left_outer_knuckle"/>
    <axis xyz="-1 0 0"/>
    <limit effort="1000" lower="0" upper="0.7" velocity="2.0"/>
  </joint>
  <joint name="left_outer_finger_joint" type="fixed">
    <origin rpy="0 0 0" xyz="0 0.01821998610742 0.0260018192872234"/>
    <parent link="left_outer_knuckle"/>
    <child link="left_outer_finger"/>
    <axis xyz="1 0 0"/>
  </joint>
  <joint name="left_inner_knuckle_joint" type="revolute">
    <origin rpy="2.2957963267948966 0 0.0" xyz="0 -0.0127 0.06142"/>
    <parent link="robotiq_arg2f_base_link"/>
    <child link="left_inner_knuckle"/>
    <axis xyz="1 0 0"/>
    <limit effort="1000" lower="-0.8757" upper="0.8757" velocity="2.0"/>
    <mimic joint="finger_joint" multiplier="-1" offset="0"/>
  </joint>
  <joint name="left_inner_finger_joint" type="revolute">
    <origin rpy="-0.725 0 0" xyz="0 0.0817554015893473 -0.0282203446692936"/>
    <parent link="left_outer_finger"/>
    <child link="left_inner_finger"/>
    <axis xyz="1 0 0"/>
    <limit effort="1000" lower="-0.8757" upper="0.8757" velocity="2.0"/>
    <mimic joint="finger_joint" multiplier="1" offset="0"/>
  </joint>
  <joint name="left_inner_finger_pad_joint" type="fixed">
    <origin rpy="0 0 0" xyz="0 0.0457554015893473 -0.0272203446692936"/>
    <parent link="left_inner_finger"/>
    <child link="left_inner_finger_pad"/>
    <axis xyz="0 0 1"/>
  </joint>
  <joint name="right_outer_knuckle_joint" type="revolute">
    <origin rpy="2.2957963267948966 0 3.141592653589793" xyz="0 0.030601 0.054905"/>
    <parent link="robotiq_arg2f_base_link"/>
    <child link="right_outer_knuckle"/>
    <axis xyz="1 0 0"/>
    <limit effort="1000" lower="-0.725" upper="0.725" velocity="2.0"/>
    <mimic joint="finger_joint" multiplier="-1" offset="0"/>
  </joint>
  <joint name="right_outer_finger_joint" type="fixed">
    <origin rpy="0 0 0" xyz="0 0.01821998610742 0.0260018192872234"/>
    <parent link="right_outer_knuckle"/>
    <child link="right_outer_finger"/>
    <axis xyz="1 0 0"/>
  </joint>
  <joint name="right_inner_knuckle_joint" type="revolute">
    <origin rpy="2.2957963267948966 0 -3.141592653589793" xyz="0 0.0127 0.06142"/>
    <parent link="robotiq_arg2f_base_link"/>
    <child link="right_inner_knuckle"/>
    <axis xyz="1 0 0"/>
    <limit effort="1000" lower="-0.8757" upper="0.8757" velocity="2.0"/>
    <mimic joint="finger_joint" multiplier="-1" offset="0"/>
  </joint>
  <joint name="right_inner_finger_joint" type="revolute">
    <origin rpy="-0.725 0 0" xyz="0 0.0817554015893473 -0.0282203446692936"/>
    <parent link="right_outer_finger"/>
    <child link="right_inner_finger"/>
    <axis xyz="1 0 0"/>
    <limit effort="1000" lower="-0.8757" upper="0.8757" velocity="2.0"/>
    <mimic joint="finger_joint" multiplier="1" offset="0"/>
  </joint>
  <joint name="right_inner_finger_pad_joint" type="fixed">
    <origin rpy="0 0 0" xyz="0 0.0457554015893473 -0.0272203446692936"/>
    <parent link="right_inner_finger"/>
    <child link="right_inner_finger_pad"/>
    <axis xyz="0 0 1"/>
  </joint>
  <transmission name="finger_joint_trans">
    <type>transmission_interface/SimpleTransmission</type>
    <joint name="finger_joint">
      <hardwareInterface>PositionJointInterface</hardwareInterface>
    </joint>
    <actuator name="finger_joint_motor">
      <mechanicalReduction>1</mechanicalReduction>
    </actuator>
  </transmission>

  <!-- 添加固定连接：把夹爪 base_link 接到机械臂末端 link -->
  <joint name="gripper_to_robot_fixed" type="fixed">
    <parent link="ARM7"/> <!-- 替换为你的机械臂末端 link 名称 -->
    <child  link="robotiq_arg2f_base_link"/> <!-- 替换为你的夹爪 base link 名称 -->
    <origin xyz="0 0 0" rpy="0 0 1.571"/> <!-- 视实际姿态调整位置与方向 -->
  </joint>

</robot>
