<?xml version="1.0" encoding="UTF-8"?>
<robot name="gbt-c12a">
  <joint name="AssemblerFixedJoint" type="fixed">
    <origin xyz="0. 0. -0." rpy="0. 0.0000002 1.5707964"/>
    <parent link="GBT_C12A_link6"/>
    <child link="ee_link_robotiq_arg2f_base_link"/>
  </joint>
  <joint name="finger_joint" type="revolute">
    <origin xyz="0. -0.030601 0.054905" rpy="-2.2957964 0. -3.1415927"/>
    <parent link="ee_link_robotiq_arg2f_base_link"/>
    <child link="left_outer_knuckle"/>
    <axis xyz="1. 0. 0."/>
    <limit lower="0." upper="0.7" effort="200." velocity="1.9999999"/>
  </joint>
  <joint name="joint1" type="revolute">
    <origin xyz="0. 0. 0.196" rpy="0. 0. 0."/>
    <parent link="GBT_C12A_base_link"/>
    <child link="GBT_C12A_link1"/>
    <axis xyz="0. 0. 1."/>
    <limit lower="-6.2831853" upper="6.2831853" effort="100." velocity="0.9999999"/>
  </joint>
  <joint name="joint2" type="revolute">
    <origin xyz="0. 0.184 0. " rpy="1.5707964 0. 0. "/>
    <parent link="GBT_C12A_link1"/>
    <child link="GBT_C12A_link2"/>
    <axis xyz="0. 0. 1."/>
    <limit lower="-1.4835297" upper="4.6251225" effort="100." velocity="0.9999999"/>
  </joint>
  <joint name="joint3" type="revolute">
    <origin xyz="0.6125 -0. 0.148 " rpy="0. 0. 0."/>
    <parent link="GBT_C12A_link2"/>
    <child link="GBT_C12A_link3"/>
    <axis xyz="0. 0. 1."/>
    <limit lower="-2.879793" upper="2.879793" effort="100." velocity="0.9999999"/>
  </joint>
  <joint name="joint4" type="revolute">
    <origin xyz="0.5605 -0. -0.1308" rpy="0. 0. 0."/>
    <parent link="GBT_C12A_link3"/>
    <child link="GBT_C12A_link4"/>
    <axis xyz="0. 0. 1."/>
    <limit lower="-1.4835297" upper="4.6251225" effort="100." velocity="0.9999999"/>
  </joint>
  <joint name="joint5" type="revolute">
    <origin xyz="-0.0000001 -0.1308 0. " rpy="1.5707964 0. 0. "/>
    <parent link="GBT_C12A_link4"/>
    <child link="GBT_C12A_link5"/>
    <axis xyz="0. 0. 1."/>
    <limit lower="-6.2831853" upper="6.2831853" effort="100." velocity="0.9999999"/>
  </joint>
  <joint name="joint6" type="revolute">
    <origin xyz="0. -0.1163 0. " rpy="1.5707963 0. 0. "/>
    <parent link="GBT_C12A_link5"/>
    <child link="GBT_C12A_link6"/>
    <axis xyz="0. 0. 1."/>
    <limit lower="-6.2831853" upper="6.2831853" effort="100." velocity="0.9999999"/>
  </joint>
  <joint name="left_inner_finger_joint" type="revolute">
    <origin xyz="0. -0.0999754 -0.0022185" rpy="-0.725 0. 3.1415927"/>
    <parent link="left_outer_knuckle"/>
    <child link="left_inner_finger"/>
    <axis xyz="1. 0. 0."/>
    <limit lower="-0.14" upper="0.84" effort="0." velocity="17453.2925199"/>
  </joint>
  <joint name="left_inner_knuckle_joint" type="revolute">
    <origin xyz="0. -0.0127 0.06142" rpy="2.2957964 0. 0. "/>
    <parent link="ee_link_robotiq_arg2f_base_link"/>
    <child link="left_inner_knuckle"/>
    <axis xyz="1. 0. 0."/>
    <limit lower="-0.84" upper="0.14" effort="0." velocity="17453.2925199"/>
  </joint>
  <joint name="right_inner_finger_joint" type="revolute">
    <origin xyz="0. 0.0999754 -0.0022185" rpy="-0.725 0. 0. "/>
    <parent link="right_outer_knuckle"/>
    <child link="right_inner_finger"/>
    <axis xyz="1. 0. 0."/>
    <limit lower="-0.14" upper="0.84" effort="0." velocity="17453.2925199"/>
  </joint>
  <joint name="right_inner_knuckle_joint" type="revolute">
    <origin xyz="0. 0.0127 0.06142" rpy="2.2957964 0. 3.1415925"/>
    <parent link="ee_link_robotiq_arg2f_base_link"/>
    <child link="right_inner_knuckle"/>
    <axis xyz="1. 0. 0."/>
    <limit lower="-0.84" upper="0.14" effort="0." velocity="17453.2925199"/>
  </joint>
  <joint name="right_outer_knuckle_joint" type="revolute">
    <origin xyz="0. 0.030601 0.054905" rpy="2.2957964 0. -3.1415925"/>
    <parent link="ee_link_robotiq_arg2f_base_link"/>
    <child link="right_outer_knuckle"/>
    <axis xyz="1. 0. 0."/>
    <limit lower="-0.84" upper="0.14" effort="0." velocity="17453.2925199"/>
  </joint>
  <joint name="root_joint" type="fixed">
    <origin xyz="0. 0. 0." rpy="0. 0. 0."/>
    <parent link="GBT_C12A"/>
    <child link="GBT_C12A_base_link"/>
  </joint>
  <link name="GBT_C12A"/>
  <link name="GBT_C12A_base_link">
    <inertial>
      <origin xyz="0.0000013 -0.0061641 0.051682 " rpy="0. 0. 0."/>
      <mass value="13.842"/>
      <inertia ixx="0.040221" ixy="0.0000133" ixz="-0.0000008" iyy="0.032081" iyz="0.0005899" izz="0.059352"/>
    </inertial>
    <visual>
      <origin xyz="0. 0. 0." rpy="0. 0. 0."/>
      <geometry>
        <mesh filename="./meshes/GBT_C12A_base_link_visuals_base_link_mesh.obj" scale="1. 1. 1."/>
      </geometry>
    </visual>
    <visual>
      <origin xyz="0. 0. 0." rpy="0. 0. 0."/>
      <geometry>
        <mesh filename="./meshes/GBT_C12A_base_link_collisions_base_link_mesh.obj" scale="1. 1. 1."/>
      </geometry>
    </visual>
    <collision>
      <origin xyz="0. 0. 0." rpy="0. 0. 0."/>
      <geometry>
        <mesh filename="./meshes/GBT_C12A_base_link_collisions_base_link_mesh.obj" scale="1. 1. 1."/>
      </geometry>
    </collision>
  </link>
  <link name="GBT_C12A_link1">
    <inertial>
      <origin xyz="-0.0000471 0.0057889 0.10293 " rpy="0. 0. 0."/>
      <mass value="31.1499996"/>
      <inertia ixx="0.15484" ixy="0.0000576" ixz="0.0000001" iyy="0.14949" iyz="0.0001218" izz="0.097986"/>
    </inertial>
    <visual>
      <origin xyz="0. 0. 0." rpy="0. 0. 0."/>
      <geometry>
        <mesh filename="./meshes/GBT_C12A_link1_visuals_link1_mesh.obj" scale="1. 1. 1."/>
      </geometry>
    </visual>
    <visual>
      <origin xyz="0. 0. 0." rpy="0. 0. 0."/>
      <geometry>
        <mesh filename="./meshes/GBT_C12A_link1_collisions_link1_mesh.obj" scale="1. 1. 1."/>
      </geometry>
    </visual>
    <collision>
      <origin xyz="0. 0. 0." rpy="0. 0. 0."/>
      <geometry>
        <mesh filename="./meshes/GBT_C12A_link1_collisions_link1_mesh.obj" scale="1. 1. 1."/>
      </geometry>
    </collision>
  </link>
  <link name="GBT_C12A_link2">
    <inertial>
      <origin xyz="0.25627 0.0000115 0.10281 " rpy="0. 0. 0."/>
      <mass value="88.7559967"/>
      <inertia ixx="0.27835" ixy="0.0004823" ixz="-0.0077364" iyy="5.0985994" iyz="0.0000306" izz="5.0183995"/>
    </inertial>
    <visual>
      <origin xyz="0. 0. 0." rpy="0. 0. 0."/>
      <geometry>
        <mesh filename="./meshes/GBT_C12A_link2_visuals_link2_mesh.obj" scale="1. 1. 1."/>
      </geometry>
    </visual>
    <visual>
      <origin xyz="0. 0. 0." rpy="0. 0. 0."/>
      <geometry>
        <mesh filename="./meshes/GBT_C12A_link2_collisions_link2_mesh.obj" scale="1. 1. 1."/>
      </geometry>
    </visual>
    <collision>
      <origin xyz="0. 0. 0." rpy="0. 0. 0."/>
      <geometry>
        <mesh filename="./meshes/GBT_C12A_link2_collisions_link2_mesh.obj" scale="1. 1. 1."/>
      </geometry>
    </collision>
  </link>
  <link name="GBT_C12A_link3">
    <inertial>
      <origin xyz="-0.27117 0.0000034 0.061195 " rpy="0. 0. 0."/>
      <mass value="40.5970001"/>
      <inertia ixx="0.060991" ixy="0.0000261" ixz="0.031846" iyy="1.7475001" iyz="-0.000003" izz="1.7362998"/>
    </inertial>
    <visual>
      <origin xyz="-0.0000001 -0. -0. " rpy="0. 0. 0."/>
      <geometry>
        <mesh filename="./meshes/GBT_C12A_link3_visuals_link3_mesh.obj" scale="1. 1. 1."/>
      </geometry>
    </visual>
    <visual>
      <origin xyz="-0.0000001 -0. -0. " rpy="0. 0. 0."/>
      <geometry>
        <mesh filename="./meshes/GBT_C12A_link3_collisions_link3_mesh.obj" scale="1. 1. 1."/>
      </geometry>
    </visual>
    <collision>
      <origin xyz="-0.0000001 -0. -0. " rpy="0. 0. 0."/>
      <geometry>
        <mesh filename="./meshes/GBT_C12A_link3_collisions_link3_mesh.obj" scale="1. 1. 1."/>
      </geometry>
    </collision>
  </link>
  <link name="GBT_C12A_link4">
    <inertial>
      <origin xyz="0.0000065 0.0000285 0.051524 " rpy="0. 0. 0."/>
      <mass value="8.3136997"/>
      <inertia ixx="0.019136" ixy="0.0000002" ixz="0.0000003" iyy="0.010018" iyz="-0.0000112" izz="0.017943"/>
    </inertial>
    <visual>
      <origin xyz="-0.0000001 0. 0. " rpy="0. 0. 0."/>
      <geometry>
        <mesh filename="./meshes/GBT_C12A_link4_visuals_link4_mesh.obj" scale="1. 1. 1."/>
      </geometry>
    </visual>
    <visual>
      <origin xyz="-0.0000001 0. 0. " rpy="0. 0. 0."/>
      <geometry>
        <mesh filename="./meshes/GBT_C12A_link4_collisions_link4_mesh.obj" scale="1. 1. 1."/>
      </geometry>
    </visual>
    <collision>
      <origin xyz="-0.0000001 0. 0. " rpy="0. 0. 0."/>
      <geometry>
        <mesh filename="./meshes/GBT_C12A_link4_collisions_link4_mesh.obj" scale="1. 1. 1."/>
      </geometry>
    </collision>
  </link>
  <link name="GBT_C12A_link5">
    <inertial>
      <origin xyz="-0.0000069 -0.0000031 -0.051525 " rpy="0. 0. 0."/>
      <mass value="8.316"/>
      <inertia ixx="0.019157" ixy="-0.0000003" ixz="0.0000004" iyy="0.010013" iyz="0.0000091" izz="0.017964"/>
    </inertial>
    <visual>
      <origin xyz="0. -0. 0." rpy="-0. 0. 0."/>
      <geometry>
        <mesh filename="./meshes/GBT_C12A_link5_visuals_link5_mesh.obj" scale="1. 1. 1."/>
      </geometry>
    </visual>
    <visual>
      <origin xyz="0. -0. 0." rpy="-0. 0. 0."/>
      <geometry>
        <mesh filename="./meshes/GBT_C12A_link5_collisions_link5_mesh.obj" scale="1. 1. 1."/>
      </geometry>
    </visual>
    <collision>
      <origin xyz="0. -0. 0." rpy="-0. 0. 0."/>
      <geometry>
        <mesh filename="./meshes/GBT_C12A_link5_collisions_link5_mesh.obj" scale="1. 1. 1."/>
      </geometry>
    </collision>
  </link>
  <link name="GBT_C12A_link6">
    <inertial>
      <origin xyz="0. 0.0001342 0.018933 " rpy="0. 0. 0."/>
      <mass value="1.9242001"/>
      <inertia ixx="0.0012043" ixy="0." ixz="0." iyy="0.0012178" iyz="0.0000012" izz="0.0019174"/>
    </inertial>
    <visual>
      <origin xyz="0. 0. -0." rpy="-0.0000002 0. 0. "/>
      <geometry>
        <mesh filename="./meshes/GBT_C12A_link6_visuals_link6_mesh.obj" scale="1. 1. 1."/>
      </geometry>
    </visual>
    <visual>
      <origin xyz="0. 0. -0." rpy="-0.0000002 0. 0. "/>
      <geometry>
        <mesh filename="./meshes/GBT_C12A_link6_collisions_link6_mesh.obj" scale="1. 1. 1."/>
      </geometry>
    </visual>
    <collision>
      <origin xyz="0. 0. -0." rpy="-0.0000002 0. 0. "/>
      <geometry>
        <mesh filename="./meshes/GBT_C12A_link6_collisions_link6_mesh.obj" scale="1. 1. 1."/>
      </geometry>
    </collision>
  </link>
  <link name="ee_link_robotiq_arg2f_base_link">
    <inertial>
      <origin xyz="0.0000001 -0.0000047 0.03145 " rpy="0. 0. 0."/>
      <mass value="0.22652"/>
      <inertia ixx="0.0002" ixy="-0." ixz="-0." iyy="0.0001783" iyz="-0." izz="0.0001348"/>
    </inertial>
    <visual>
      <origin xyz="0. 0. 0." rpy="0. 0. 0."/>
      <geometry>
        <mesh filename="./meshes/ee_link_robotiq_arg2f_base_link_visuals_robotiq_arg2f_base_link_mesh.obj" scale="1. 1. 1."/>
      </geometry>
    </visual>
    <visual>
      <origin xyz="0. 0. 0." rpy="0. 0. 0."/>
      <geometry>
        <mesh filename="./meshes/ee_link_robotiq_arg2f_base_link_collisions_robotiq_arg2f_base_link_mesh.obj" scale="1. 1. 1."/>
      </geometry>
    </visual>
    <collision>
      <origin xyz="0. 0. 0." rpy="0. 0. 0."/>
      <geometry>
        <mesh filename="./meshes/ee_link_robotiq_arg2f_base_link_collisions_robotiq_arg2f_base_link_mesh.obj" scale="1. 1. 1."/>
      </geometry>
    </collision>
  </link>
  <link name="left_inner_finger">
    <inertial>
      <origin xyz="0.0003 0.0160078 -0.0136946" rpy="0. 0. 0."/>
      <mass value="0.0104003"/>
      <inertia ixx="0.0000027" ixy="0." ixz="0." iyy="0.0000008" iyz="0.0000007" izz="0.0000023"/>
    </inertial>
    <visual>
      <origin xyz="0. -0. 0." rpy="-0. 0. 0."/>
      <geometry>
        <mesh filename="./meshes/left_inner_finger_visuals_robotiq_arg2f_140_inner_finger_mesh.obj" scale="1. 1. 1."/>
      </geometry>
    </visual>
    <visual>
      <origin xyz="0. 0.0457554 -0.0272203" rpy="-0. 0. 0."/>
      <geometry>
        <box size="0.027 0.065 0.0075"/>
      </geometry>
    </visual>
    <visual>
      <origin xyz="0. -0. 0." rpy="-0. 0. 0."/>
      <geometry>
        <mesh filename="./meshes/left_inner_finger_collisions_robotiq_arg2f_140_inner_finger_mesh.obj" scale="1. 1. 1."/>
      </geometry>
    </visual>
    <visual>
      <origin xyz="0. 0.0457554 -0.0272203" rpy="-0. 0. 0."/>
      <geometry>
        <box size="0.03 0.07 0.0075"/>
      </geometry>
    </visual>
    <collision>
      <origin xyz="0. -0. 0." rpy="-0. 0. 0."/>
      <geometry>
        <mesh filename="./meshes/left_inner_finger_collisions_robotiq_arg2f_140_inner_finger_mesh.obj" scale="1. 1. 1."/>
      </geometry>
    </collision>
    <collision>
      <origin xyz="0. 0.0457554 -0.0272203" rpy="-0. 0. 0."/>
      <geometry>
        <box size="0.03 0.07 0.0075"/>
      </geometry>
    </collision>
  </link>
  <link name="left_inner_knuckle">
    <inertial>
      <origin xyz="0.000123 0.0507851 0.0010397" rpy="0. 0. 0."/>
      <mass value="0.0271177"/>
      <inertia ixx="0.0000262" ixy="-0.0000002" ixz="-0." iyy="0.0000028" iyz="-0.0000005" izz="0.0000284"/>
    </inertial>
    <visual>
      <origin xyz="0. 0. 0." rpy="-0. 0. 0."/>
      <geometry>
        <mesh filename="./meshes/left_inner_knuckle_visuals_robotiq_arg2f_140_inner_knuckle_mesh.obj" scale="1. 1. 1."/>
      </geometry>
    </visual>
    <visual>
      <origin xyz="0. 0. 0." rpy="-0. 0. 0."/>
      <geometry>
        <mesh filename="./meshes/left_inner_knuckle_collisions_robotiq_arg2f_140_inner_knuckle_mesh.obj" scale="1. 1. 1."/>
      </geometry>
    </visual>
    <collision>
      <origin xyz="0. 0. 0." rpy="-0. 0. 0."/>
      <geometry>
        <mesh filename="./meshes/left_inner_knuckle_collisions_robotiq_arg2f_140_inner_knuckle_mesh.obj" scale="1. 1. 1."/>
      </geometry>
    </collision>
  </link>
  <link name="left_outer_knuckle">
    <inertial>
      <origin xyz="0.0001639 0.0458404 0.0117804" rpy="0. 0. 0."/>
      <mass value="0.0311462"/>
      <inertia ixx="0.0000296" ixy="-0.0000001" ixz="0.0000001" iyy="0.0000116" iyz="0.0000109" izz="0.0000208"/>
    </inertial>
    <visual>
      <origin xyz="0. 0. 0." rpy="-0. 0. 3.1415927"/>
      <geometry>
        <mesh filename="./meshes/left_outer_knuckle_visuals_robotiq_arg2f_140_outer_knuckle_mesh.obj" scale="1. 1. 1."/>
      </geometry>
    </visual>
    <visual>
      <origin xyz="0. -0.01822 0.0260018" rpy="-0. 0. 3.1415927"/>
      <geometry>
        <mesh filename="./meshes/left_outer_knuckle_visuals_robotiq_arg2f_140_outer_finger_mesh.obj" scale="1. 1. 1."/>
      </geometry>
    </visual>
    <visual>
      <origin xyz="0. 0. 0." rpy="-0. 0. 3.1415927"/>
      <geometry>
        <mesh filename="./meshes/left_outer_knuckle_collisions_robotiq_arg2f_140_outer_knuckle_mesh.obj" scale="1. 1. 1."/>
      </geometry>
    </visual>
    <visual>
      <origin xyz="0. -0.01822 0.0260018" rpy="-0. 0. 3.1415927"/>
      <geometry>
        <mesh filename="./meshes/left_outer_knuckle_collisions_robotiq_arg2f_140_outer_finger_mesh.obj" scale="1. 1. 1."/>
      </geometry>
    </visual>
    <collision>
      <origin xyz="0. 0. 0." rpy="-0. 0. 3.1415927"/>
      <geometry>
        <mesh filename="./meshes/left_outer_knuckle_collisions_robotiq_arg2f_140_outer_knuckle_mesh.obj" scale="1. 1. 1."/>
      </geometry>
    </collision>
    <collision>
      <origin xyz="0. -0.01822 0.0260018" rpy="-0. 0. 3.1415927"/>
      <geometry>
        <mesh filename="./meshes/left_outer_knuckle_collisions_robotiq_arg2f_140_outer_finger_mesh.obj" scale="1. 1. 1."/>
      </geometry>
    </collision>
  </link>
  <link name="right_inner_finger">
    <inertial>
      <origin xyz="0.0003 0.0160078 -0.0136946" rpy="0. 0. 0."/>
      <mass value="0.0104003"/>
      <inertia ixx="0.0000027" ixy="0." ixz="0." iyy="0.0000008" iyz="0.0000007" izz="0.0000023"/>
    </inertial>
    <visual>
      <origin xyz="0. 0. 0." rpy="0. 0. 0."/>
      <geometry>
        <mesh filename="./meshes/right_inner_finger_visuals_robotiq_arg2f_140_inner_finger_mesh.obj" scale="1. 1. 1."/>
      </geometry>
    </visual>
    <visual>
      <origin xyz="0. 0.0457554 -0.0272203" rpy="0. 0. 0."/>
      <geometry>
        <box size="0.027 0.065 0.0075"/>
      </geometry>
    </visual>
    <visual>
      <origin xyz="0. 0. 0." rpy="0. 0. 0."/>
      <geometry>
        <mesh filename="./meshes/right_inner_finger_collisions_robotiq_arg2f_140_inner_finger_mesh.obj" scale="1. 1. 1."/>
      </geometry>
    </visual>
    <visual>
      <origin xyz="0. 0.0457554 -0.0272203" rpy="0. 0. 0."/>
      <geometry>
        <box size="0.03 0.07 0.0075"/>
      </geometry>
    </visual>
    <collision>
      <origin xyz="0. 0. 0." rpy="0. 0. 0."/>
      <geometry>
        <mesh filename="./meshes/right_inner_finger_collisions_robotiq_arg2f_140_inner_finger_mesh.obj" scale="1. 1. 1."/>
      </geometry>
    </collision>
    <collision>
      <origin xyz="0. 0.0457554 -0.0272203" rpy="0. 0. 0."/>
      <geometry>
        <box size="0.03 0.07 0.0075"/>
      </geometry>
    </collision>
  </link>
  <link name="right_inner_knuckle">
    <inertial>
      <origin xyz="0.000123 0.0507851 0.0010397" rpy="0. 0. 0."/>
      <mass value="0.0271177"/>
      <inertia ixx="0.0000262" ixy="-0.0000002" ixz="-0." iyy="0.0000028" iyz="-0.0000005" izz="0.0000284"/>
    </inertial>
    <visual>
      <origin xyz="0. 0. 0." rpy="0. 0. 0."/>
      <geometry>
        <mesh filename="./meshes/right_inner_knuckle_visuals_robotiq_arg2f_140_inner_knuckle_mesh.obj" scale="1. 1. 1."/>
      </geometry>
    </visual>
    <visual>
      <origin xyz="0. 0. 0." rpy="0. 0. 0."/>
      <geometry>
        <mesh filename="./meshes/right_inner_knuckle_collisions_robotiq_arg2f_140_inner_knuckle_mesh.obj" scale="1. 1. 1."/>
      </geometry>
    </visual>
    <collision>
      <origin xyz="0. 0. 0." rpy="0. 0. 0."/>
      <geometry>
        <mesh filename="./meshes/right_inner_knuckle_collisions_robotiq_arg2f_140_inner_knuckle_mesh.obj" scale="1. 1. 1."/>
      </geometry>
    </collision>
  </link>
  <link name="right_outer_knuckle">
    <inertial>
      <origin xyz="0.0001639 0.0458404 0.0117804" rpy="0. 0. 0."/>
      <mass value="0.0311462"/>
      <inertia ixx="0.0000296" ixy="-0.0000001" ixz="0.0000001" iyy="0.0000116" iyz="0.0000109" izz="0.0000208"/>
    </inertial>
    <visual>
      <origin xyz="0. 0. 0." rpy="0. 0. 0."/>
      <geometry>
        <mesh filename="./meshes/right_outer_knuckle_visuals_robotiq_arg2f_140_outer_knuckle_mesh.obj" scale="1. 1. 1."/>
      </geometry>
    </visual>
    <visual>
      <origin xyz="0. 0.01822 0.0260018" rpy="0. 0. 0."/>
      <geometry>
        <mesh filename="./meshes/right_outer_knuckle_visuals_robotiq_arg2f_140_outer_finger_mesh.obj" scale="1. 1. 1."/>
      </geometry>
    </visual>
    <visual>
      <origin xyz="0. 0. 0." rpy="0. 0. 0."/>
      <geometry>
        <mesh filename="./meshes/right_outer_knuckle_collisions_robotiq_arg2f_140_outer_knuckle_mesh.obj" scale="1. 1. 1."/>
      </geometry>
    </visual>
    <visual>
      <origin xyz="0. 0.01822 0.0260018" rpy="0. 0. 0."/>
      <geometry>
        <mesh filename="./meshes/right_outer_knuckle_collisions_robotiq_arg2f_140_outer_finger_mesh.obj" scale="1. 1. 1."/>
      </geometry>
    </visual>
    <collision>
      <origin xyz="0. 0. 0." rpy="0. 0. 0."/>
      <geometry>
        <mesh filename="./meshes/right_outer_knuckle_collisions_robotiq_arg2f_140_outer_knuckle_mesh.obj" scale="1. 1. 1."/>
      </geometry>
    </collision>
    <collision>
      <origin xyz="0. 0.01822 0.0260018" rpy="0. 0. 0."/>
      <geometry>
        <mesh filename="./meshes/right_outer_knuckle_collisions_robotiq_arg2f_140_outer_finger_mesh.obj" scale="1. 1. 1."/>
      </geometry>
    </collision>
  </link>
</robot>
