<?xml version="1.0"?>
<robot name="GBT_C5A" xmlns:xacro="http://www.ros.org/wiki/xacro">

  <!-- Base Link: base_link -->
  <link name="base_link">
    <inertial>
      <origin xyz="-0.000115 -0.003836 0.044852" rpy="0 0 0"/>
      <mass value="1.489536"/>
      <inertia
        ixx="0.004543"
        ixy="-0.000001"
        ixz="-0.000011"
        iyy="0.003119"
        iyz="0.000197"
        izz="0.005800"/>
    </inertial>
    <visual>
      <origin xyz="0 0 0" rpy="0 0 0"/>
      <geometry>
        <mesh filename="../meshes/visual/base_link.obj" scale="0.001 0.001 0.001"/>
      </geometry>
    </visual>
    <collision>
      <origin xyz="0 0 0" rpy="0 0 0"/>
      <geometry>
        <mesh filename="../meshes/collision/base_link.stl" scale="0.001 0.001 0.001"/>
      </geometry>
    </collision>
  </link>

  <!-- link1 -->
  <joint name="joint1" type="revolute">
    <parent link="base_link"/>
    <child link="link1"/>
    <origin xyz="0 0 0.178" rpy="0 0 0"/>
    <axis xyz="0 0 1"/>
    <limit effort="100" lower="-6.283185307179" upper="6.283185307179" velocity="1"/>
  </joint>
  <link name="link1">
    <inertial>
      <origin xyz="-0.000366 0.001960 -0.027035" rpy="0 0 0"/>
      <mass value="4.763058"/>
      <inertia
        ixx="0.010679"
        ixy="0.000040"
        ixz="-0.000058"
        iyy="0.010619"
        iyz="0.000214"
        izz="0.008154"/>
    </inertial>
    <visual>
      <origin xyz="0 0 0" rpy="0 0 0"/>
      <geometry>
        <mesh filename="../meshes/visual/link1.obj" scale="0.001 0.001 0.001"/>
      </geometry>
    </visual>
    <collision>
      <origin xyz="0 0 0" rpy="0 0 0"/>
      <geometry>
        <mesh filename="../meshes/collision/link1.stl" scale="0.001 0.001 0.001"/>
      </geometry>
    </collision>
  </link>

  <!-- link2 -->
  <joint name="joint2" type="revolute">
    <parent link="link1"/>
    <child link="link2"/>
    <origin xyz="0 0.147 0" rpy="1.5707963267948966 0 0"/>
    <axis xyz="0 0 1"/>
    <limit effort="100" lower="-1.483529864195" upper="4.625122517784" velocity="1"/>
  </joint>
  <link name="link2">
    <inertial>
      <origin xyz="0.212421 0.000000 0.023494" rpy="0 0 0"/>
      <mass value="10.922830"/>
      <inertia
        ixx="0.025117"
        ixy="0.000815"
        ixz="0.000075"
        iyy="0.463693"
        iyz="0.000001"
        izz="0.457686"/>
    </inertial>
    <visual>
      <origin xyz="0 0 0" rpy="0 0 0"/>
      <geometry>
        <mesh filename="../meshes/visual/link2.obj" scale="0.001 0.001 0.001"/>
      </geometry>
    </visual>
    <collision>
      <origin xyz="0 0 0" rpy="0 0 0"/>
      <geometry>
        <mesh filename="../meshes/collision/link2.stl" scale="0.001 0.001 0.001"/>
      </geometry>
    </collision>
  </link>

  <!-- link3 -->
  <joint name="joint3" type="revolute">
    <parent link="link2"/>
    <child link="link3"/>
    <origin xyz="0.425 0 0.072" rpy="0 0 0"/>
    <axis xyz="0 0 1"/>
    <limit effort="100" lower="-2.879793265790" upper="2.879793265790" velocity="1"/>
  </joint>
  <link name="link3">
    <inertial>
      <origin xyz="0.240843 -0.000259 0.057044" rpy="0 0 0"/>
      <mass value="3.817807"/>
      <inertia
        ixx="0.006786"
        ixy="-0.000147"
        ixz="-0.001424"
        iyy="0.104226"
        iyz="-0.000012"
        izz="0.102926"/>
    </inertial>
    <visual>
      <origin xyz="0 0 0" rpy="0 0 0"/>
      <geometry>
        <mesh filename="../meshes/visual/link3.obj" scale="0.001 0.001 0.001"/>
      </geometry>
    </visual>
    <collision>
      <origin xyz="0 0 0" rpy="0 0 0"/>
      <geometry>
        <mesh filename="../meshes/collision/link3.stl" scale="0.001 0.001 0.001"/>
      </geometry>
    </collision>
  </link>

  <!-- link4 -->
  <joint name="joint4" type="revolute">
    <parent link="link3"/>
    <child link="link4"/>
    <origin xyz="0.385 0 -0.052" rpy="0 0 0"/>
    <axis xyz="0 0 1"/>
    <limit effort="100" lower="-1.483529864195" upper="4.625122517784" velocity="1"/>
  </joint>
  <link name="link4">
    <inertial>
      <origin xyz="0.000527 -0.017542 -0.002802" rpy="0 0 0"/>
      <mass value="1.860492"/>
      <inertia
        ixx="0.003113"
        ixy="0.000018"
        ixz="-0.000009"
        iyy="0.01678"
        iyz="0.000064"
        izz="0.002995"/>
    </inertial>
    <visual>
      <origin xyz="0 0 0" rpy="0 0 0"/>
      <geometry>
        <mesh filename="../meshes/visual/link4.obj" scale="0.001 0.001 0.001"/>
      </geometry>
    </visual>
    <collision>
      <origin xyz="0 0 0" rpy="0 0 0"/>
      <geometry>
        <mesh filename="../meshes/collision/link4.stl" scale="0.001 0.001 0.001"/>
      </geometry>
    </collision>
  </link>

  <!-- link5 -->
  <joint name="joint5" type="revolute">
    <parent link="link4"/>
    <child link="link5"/>
    <origin xyz="0 -0.1233 0" rpy="1.5707963267948966 0 0"/>
    <axis xyz="0 0 1"/>
    <limit effort="100" lower="-6.283185307179" upper="6.283185307179" velocity="1"/>
  </joint>
  <link name="link5">
    <inertial>
      <origin xyz="-0.000539 -0.018034 -0.003263" rpy="0 0 0"/>
      <mass value="1.823601"/>
      <inertia
        ixx="0.003117"
        ixy="-0.000019"
        ixz="-0.000008"
        iyy="0.01590"
        iyz="-0.000099"
        izz="0.003001"/>
    </inertial>
    <visual>
      <origin xyz="0 0 0" rpy="0 0 0"/>
      <geometry>
        <mesh filename="../meshes/visual/link5.obj" scale="0.001 0.001 0.001"/>
      </geometry>
    </visual>
    <collision>
      <origin xyz="0 0 0" rpy="0 0 0"/>
      <geometry>
        <mesh filename="../meshes/collision/link5.stl" scale="0.001 0.001 0.001"/>
      </geometry>
    </collision>
  </link>

  <!-- link6 -->
  <joint name="joint6" type="revolute">
    <parent link="link5"/>
    <child link="link6"/>
    <origin xyz="0 -0.1003 0" rpy="1.5707963267948966 0 0"/>
    <axis xyz="0 0 1"/>
    <limit effort="100" lower="-6.283185307179" upper="6.283185307179" velocity="1"/>
  </joint>
  <link name="link6">
    <inertial>
      <origin xyz="-0.000012 -0.000333 -0.014577" rpy="0 0 0"/>
      <mass value="0.240531"/>
      <inertia
        ixx="0.000135"
        ixy="0.000000"
        ixz="0.000000"
        iyy="0.000132"
        iyz="0.000000"
        izz="0.000234"/>
    </inertial>
    <visual>
      <origin xyz="0 0 0" rpy="0 0 0"/>
      <geometry>
        <mesh filename="../meshes/visual/link6.obj" scale="0.001 0.001 0.001"/>
      </geometry>
    </visual>
    <collision>
      <origin xyz="0 0 0" rpy="0 0 0"/>
      <geometry>
        <mesh filename="../meshes/collision/link6.stl" scale="0.001 0.001 0.001"/>
      </geometry>
    </collision>
  </link>

  <!-- 创建一个名为flange的固定link,用来标记flange末端 -->
  <link name="flange" ></link>
  <joint name="link6_flange" type="fixed">
    <parent link="link6"/>
    <child link="flange"/>
    <origin xyz="0 0 0" rpy="0 0 0"/>
  </joint>

  <link name="camera_mount">
    <visual>
      <origin xyz="0 0 0" rpy="0 0 0"/>
      <geometry>
        <mesh filename="../meshes/collision/EF_Camera_Stand_V1_2.stl" scale="0.001 0.001 0.001"/>
      </geometry>
    </visual>
    <collision>
      <origin xyz="0 0 0" rpy="0 0 0"/>
      <geometry>
        <mesh filename="../meshes/collision/EF_Camera_Stand_V1_2.stl" scale="0.001 0.001 0.001"/>
      </geometry>
    </collision>
  </link>
  <joint name="camera_mount_joint" type="fixed">
    <parent link="flange"/>
    <child link="camera_mount"/>
    <origin xyz="0 0 0.003" rpy="0 0 0"/>
  </joint>

  <!-- End Effector Link -->
  <link name="ee_link"></link>
  
  <joint name="camera_mount_ee_joint" type="fixed">
    <parent link="camera_mount"/>
    <child link="ee_link"/>
    <origin xyz="0 0 0.015" rpy="0 0 0"/>
  </joint>

  <!-- 将ee_link下挂载robotiq_arg2f_base_link -->
  <joint name="ee_link_root_joint" type="fixed">
    <parent link="ee_link"/>
    <child link="robotiq_arg2f_base_link"/>
    <origin xyz="0 0 0" rpy="0 0 1.5707963268"/>
  </joint>



  <!-- =======================gripper============================= -->
  <link name="robotiq_arg2f_base_link">
    <inertial>
      <origin rpy="0 0 0" xyz="8.625E-08 -4.6583E-06 0.03145"/>
      <mass value="0.22652"/>
      <inertia ixx="0.00020005" ixy="-4.2442E-10" ixz="-2.9069E-10" iyy="0.00017832" iyz="-3.4402E-08" izz="0.00013478"/>
    </inertial>
    <visual>
      <origin rpy="0 0 0" xyz="0 0 0"/>
      <geometry>
        <mesh filename="../meshes/visual/robotiq_arg2f_base_link.stl"/>
      </geometry>
      <material name="">
        <color rgba="0.1 0.1 0.1 1"/>
      </material>
    </visual>
    <collision>
      <origin rpy="0 0 0" xyz="0 0 0"/>
      <geometry>
        <mesh filename="../meshes/collision/robotiq_arg2f_base_link.stl"/>
      </geometry>
    </collision>
  </link>
  <link name="left_outer_knuckle">
    <inertial>
      <origin rpy="0 0 0" xyz="-0.000200000000003065 0.0199435877845359 0.0292245259211331"/>
      <mass value="0.00853198276973456"/>
      <inertia ixx="2.89328108496468E-06" ixy="-1.57935047237397E-19" ixz="-1.93980378593255E-19" iyy="1.86719750325683E-06" iyz="-1.21858577871576E-06" izz="1.21905238907251E-06"/>
    </inertial>
    <visual>
      <origin rpy="0 0 0" xyz="0 0 0"/>
      <geometry>
        <mesh filename="../meshes/visual/robotiq_arg2f_140_outer_knuckle.stl"/>
      </geometry>
      <material name="">
        <color rgba="0.792156862745098 0.819607843137255 0.933333333333333 1"/>
      </material>
    </visual>
    <collision>
      <origin rpy="0 0 0" xyz="0 0 0"/>
      <geometry>
        <mesh filename="../meshes/collision/robotiq_arg2f_140_outer_knuckle.stl"/>
      </geometry>
    </collision>
  </link>
  <link name="left_outer_finger">
    <inertial>
      <origin rpy="0 0 0" xyz="0.00030115855001899 0.0373907951953854 -0.0208027427000385"/>
      <mass value="0.022614240507152"/>
      <inertia ixx="1.52518312458174E-05" ixy="9.76583423954399E-10" ixz="-5.43838577022588E-10" iyy="6.17694243867776E-06" iyz="6.78636130740228E-06" izz="1.16494917907219E-05"/>
    </inertial>
    <visual>
      <origin rpy="0 0 0" xyz="0 0 0"/>
      <geometry>
        <mesh filename="../meshes/visual/robotiq_arg2f_140_outer_finger.stl"/>
      </geometry>
      <material name="">
        <color rgba="0.1 0.1 0.1 1"/>
      </material>
    </visual>
    <collision>
      <origin rpy="0 0 0" xyz="0 0 0"/>
      <geometry>
        <mesh filename="../meshes/collision/robotiq_arg2f_140_outer_finger.stl"/>
      </geometry>
    </collision>
  </link>
  <link name="left_inner_finger">
    <inertial>
      <origin rpy="0 0 0" xyz="0.000299999999999317 0.0160078233491243 -0.0136945669206257"/>
      <mass value="0.0104003125914103"/>
      <inertia ixx="2.71909453810972E-06" ixy="1.35402465472579E-21" ixz="-7.1817349065269E-22" iyy="7.69100314106116E-07" iyz="6.74715432769696E-07" izz="2.30315190420171E-06"/>
    </inertial>
    <visual>
      <origin rpy="0 0 0" xyz="0 0 0"/>
      <geometry>
        <mesh filename="../meshes/visual/robotiq_arg2f_140_inner_finger.stl"/>
      </geometry>
      <material name="">
        <color rgba="0.1 0.1 0.1 1"/>
      </material>
    </visual>
    <collision>
      <origin rpy="0 0 0" xyz="0 0 0"/>
      <geometry>
        <mesh filename="../meshes/collision/robotiq_arg2f_140_inner_finger.stl"/>
      </geometry>
    </collision>
  </link>
  <link name="left_inner_finger_pad">
    <visual>
      <origin rpy="0 0 0" xyz="0 0 0"/>
      <geometry>
        <box size="0.027 0.065 0.0075"/>
      </geometry>
      <material name="">
        <color rgba="0.9 0.9 0.9 1"/>
      </material>
    </visual>
    <collision>
      <origin rpy="0 0 0" xyz="0 0 0"/>
      <geometry>
        <box size="0.03 0.07 0.0075"/>
      </geometry>
      <material name="">
        <color rgba="0.9 0.0 0.0 1"/>
      </material>
    </collision>
  </link>
  <link name="left_inner_knuckle">
    <inertial>
      <origin rpy="0 0 0" xyz="0.000123011831763771 0.0507850843201817 0.00103968640075166"/>
      <mass value="0.0271177346495152"/>
      <inertia ixx="2.61910379223783E-05" ixy="-2.43616858946494E-07" ixz="-6.37789906117123E-09" iyy="2.8270243746167E-06" iyz="-5.37200748039765E-07" izz="2.83695868220296E-05"/>
    </inertial>
    <visual>
      <origin rpy="0 0 0" xyz="0 0 0"/>
      <geometry>
        <mesh filename="../meshes/visual/robotiq_arg2f_140_inner_knuckle.stl"/>
      </geometry>
      <material name="">
        <color rgba="0.1 0.1 0.1 1"/>
      </material>
    </visual>
    <collision>
      <origin rpy="0 0 0" xyz="0 0 0"/>
      <geometry>
        <mesh filename="../meshes/collision/robotiq_arg2f_140_inner_knuckle.stl"/>
      </geometry>
    </collision>
  </link>
  <link name="right_outer_knuckle">
    <inertial>
      <origin rpy="0 0 0" xyz="-0.000200000000003065 0.0199435877845359 0.0292245259211331"/>
      <mass value="0.00853198276973456"/>
      <inertia ixx="2.89328108496468E-06" ixy="-1.57935047237397E-19" ixz="-1.93980378593255E-19" iyy="1.86719750325683E-06" iyz="-1.21858577871576E-06" izz="1.21905238907251E-06"/>
    </inertial>
    <visual>
      <origin rpy="0 0 0" xyz="0 0 0"/>
      <geometry>
        <mesh filename="../meshes/visual/robotiq_arg2f_140_outer_knuckle.stl"/>
      </geometry>
      <material name="">
        <color rgba="0.792156862745098 0.819607843137255 0.933333333333333 1"/>
      </material>
    </visual>
    <collision>
      <origin rpy="0 0 0" xyz="0 0 0"/>
      <geometry>
        <mesh filename="../meshes/collision/robotiq_arg2f_140_outer_knuckle.stl"/>
      </geometry>
    </collision>
  </link>
  <link name="right_outer_finger">
    <inertial>
      <origin rpy="0 0 0" xyz="0.00030115855001899 0.0373907951953854 -0.0208027427000385"/>
      <mass value="0.022614240507152"/>
      <inertia ixx="1.52518312458174E-05" ixy="9.76583423954399E-10" ixz="-5.43838577022588E-10" iyy="6.17694243867776E-06" iyz="6.78636130740228E-06" izz="1.16494917907219E-05"/>
    </inertial>
    <visual>
      <origin rpy="0 0 0" xyz="0 0 0"/>
      <geometry>
        <mesh filename="../meshes/visual/robotiq_arg2f_140_outer_finger.stl"/>
      </geometry>
      <material name="">
        <color rgba="0.1 0.1 0.1 1"/>
      </material>
    </visual>
    <collision>
      <origin rpy="0 0 0" xyz="0 0 0"/>
      <geometry>
        <mesh filename="../meshes/collision/robotiq_arg2f_140_outer_finger.stl"/>
      </geometry>
    </collision>
  </link>
  <link name="right_inner_finger">
    <inertial>
      <origin rpy="0 0 0" xyz="0.000299999999999317 0.0160078233491243 -0.0136945669206257"/>
      <mass value="0.0104003125914103"/>
      <inertia ixx="2.71909453810972E-06" ixy="1.35402465472579E-21" ixz="-7.1817349065269E-22" iyy="7.69100314106116E-07" iyz="6.74715432769696E-07" izz="2.30315190420171E-06"/>
    </inertial>
    <visual>
      <origin rpy="0 0 0" xyz="0 0 0"/>
      <geometry>
        <mesh filename="../meshes/visual/robotiq_arg2f_140_inner_finger.stl"/>
      </geometry>
      <material name="">
        <color rgba="0.1 0.1 0.1 1"/>
      </material>
    </visual>
    <collision>
      <origin rpy="0 0 0" xyz="0 0 0"/>
      <geometry>
        <mesh filename="../meshes/collision/robotiq_arg2f_140_inner_finger.stl"/>
      </geometry>
    </collision>
  </link>
  <link name="right_inner_finger_pad">
    <visual>
      <origin rpy="0 0 0" xyz="0 0 0"/>
      <geometry>
        <box size="0.027 0.065 0.0075"/>
      </geometry>
      <material name="">
        <color rgba="0.9 0.9 0.9 1"/>
      </material>
    </visual>
    <collision>
      <origin rpy="0 0 0" xyz="0 0 0"/>
      <geometry>
        <box size="0.03 0.07 0.0075"/>
      </geometry>
      <material name="">
        <color rgba="0.9 0.0 0.0 1"/>
      </material>
    </collision>
  </link>
  <link name="right_inner_knuckle">
    <inertial>
      <origin rpy="0 0 0" xyz="0.000123011831763771 0.0507850843201817 0.00103968640075166"/>
      <mass value="0.0271177346495152"/>
      <inertia ixx="2.61910379223783E-05" ixy="-2.43616858946494E-07" ixz="-6.37789906117123E-09" iyy="2.8270243746167E-06" iyz="-5.37200748039765E-07" izz="2.83695868220296E-05"/>
    </inertial>
    <visual>
      <origin rpy="0 0 0" xyz="0 0 0"/>
      <geometry>
        <mesh filename="../meshes/visual/robotiq_arg2f_140_inner_knuckle.stl"/>
      </geometry>
      <material name="">
        <color rgba="0.1 0.1 0.1 1"/>
      </material>
    </visual>
    <collision>
      <origin rpy="0 0 0" xyz="0 0 0"/>
      <geometry>
        <mesh filename="../meshes/collision/robotiq_arg2f_140_inner_knuckle.stl"/>
      </geometry>
    </collision>
  </link>
  <joint name="finger_joint" type="revolute">
    <origin rpy="2.2957963267948966 0 0" xyz="0 -0.030601 0.054905"/>
    <parent link="robotiq_arg2f_base_link"/>
    <child link="left_outer_knuckle"/>
    <axis xyz="-1 0 0"/>
    <limit effort="1000" lower="0" upper="0.7" velocity="2.0"/>
  </joint>
  <joint name="left_outer_finger_joint" type="fixed">
    <origin rpy="0 0 0" xyz="0 0.01821998610742 0.0260018192872234"/>
    <parent link="left_outer_knuckle"/>
    <child link="left_outer_finger"/>
    <axis xyz="1 0 0"/>
  </joint>
  <joint name="left_inner_knuckle_joint" type="revolute">
    <origin rpy="2.2957963267948966 0 0.0" xyz="0 -0.0127 0.06142"/>
    <parent link="robotiq_arg2f_base_link"/>
    <child link="left_inner_knuckle"/>
    <axis xyz="1 0 0"/>
    <limit effort="1000" lower="-0.8757" upper="0.8757" velocity="2.0"/>
    <mimic joint="finger_joint" multiplier="-1" offset="0"/>
  </joint>
  <joint name="left_inner_finger_joint" type="revolute">
    <origin rpy="-0.725 0 0" xyz="0 0.0817554015893473 -0.0282203446692936"/>
    <parent link="left_outer_finger"/>
    <child link="left_inner_finger"/>
    <axis xyz="1 0 0"/>
    <limit effort="1000" lower="-0.8757" upper="0.8757" velocity="2.0"/>
    <mimic joint="finger_joint" multiplier="1" offset="0"/>
  </joint>
  <joint name="left_inner_finger_pad_joint" type="fixed">
    <origin rpy="0 0 0" xyz="0 0.0457554015893473 -0.0272203446692936"/>
    <parent link="left_inner_finger"/>
    <child link="left_inner_finger_pad"/>
    <axis xyz="0 0 1"/>
  </joint>
  <joint name="right_outer_knuckle_joint" type="revolute">
    <origin rpy="2.2957963267948966 0 3.141592653589793" xyz="0 0.030601 0.054905"/>
    <parent link="robotiq_arg2f_base_link"/>
    <child link="right_outer_knuckle"/>
    <axis xyz="1 0 0"/>
    <limit effort="1000" lower="-0.725" upper="0.725" velocity="2.0"/>
    <mimic joint="finger_joint" multiplier="-1" offset="0"/>
  </joint>
  <joint name="right_outer_finger_joint" type="fixed">
    <origin rpy="0 0 0" xyz="0 0.01821998610742 0.0260018192872234"/>
    <parent link="right_outer_knuckle"/>
    <child link="right_outer_finger"/>
    <axis xyz="1 0 0"/>
  </joint>
  <joint name="right_inner_knuckle_joint" type="revolute">
    <origin rpy="2.2957963267948966 0 -3.141592653589793" xyz="0 0.0127 0.06142"/>
    <parent link="robotiq_arg2f_base_link"/>
    <child link="right_inner_knuckle"/>
    <axis xyz="1 0 0"/>
    <limit effort="1000" lower="-0.8757" upper="0.8757" velocity="2.0"/>
    <mimic joint="finger_joint" multiplier="-1" offset="0"/>
  </joint>
  <joint name="right_inner_finger_joint" type="revolute">
    <origin rpy="-0.725 0 0" xyz="0 0.0817554015893473 -0.0282203446692936"/>
    <parent link="right_outer_finger"/>
    <child link="right_inner_finger"/>
    <axis xyz="1 0 0"/>
    <limit effort="1000" lower="-0.8757" upper="0.8757" velocity="2.0"/>
    <mimic joint="finger_joint" multiplier="1" offset="0"/>
  </joint>
  <joint name="right_inner_finger_pad_joint" type="fixed">
    <origin rpy="0 0 0" xyz="0 0.0457554015893473 -0.0272203446692936"/>
    <parent link="right_inner_finger"/>
    <child link="right_inner_finger_pad"/>
    <axis xyz="0 0 1"/>
  </joint>
  <transmission name="finger_joint_trans">
    <type>transmission_interface/SimpleTransmission</type>
    <joint name="finger_joint">
      <hardwareInterface>PositionJointInterface</hardwareInterface>
    </joint>
    <actuator name="finger_joint_motor">
      <mechanicalReduction>1</mechanicalReduction>
    </actuator>
  </transmission>

  <!-- ==================================camera===================================== -->
  <joint name="camera_mount_orbbec_joint" type="fixed">
    <origin xyz="0 -0.13 0.06" rpy="1.5707963268  1.5707963268 0"/>
    <parent link="camera_mount"/>
    <child link="Orbbec"/>
  </joint>
  <joint name="joint_Orbbec-camera_rgb" type="fixed">
    <origin xyz="-0.0554185 0.03 -0. " rpy="1.5707964 0. 1.5707964"/>
    <parent link="Orbbec"/>
    <child link="camera_rgb"/>
  </joint>
  <joint name="joint_Orbbec-camera_tof_nfov" type="fixed">
    <origin xyz="-0.0575704 -0.0019986 0.001471 " rpy="1.4660766 -0. 1.5707964"/>
    <parent link="Orbbec"/>
    <child link="camera_tof_nfov"/>
  </joint>
  <joint name="joint_Orbbec-camera_tof_wfov" type="fixed">
    <origin xyz="-0.0575704 -0.0019986 0.001471 " rpy="1.4660766 -0. 1.5707964"/>
    <parent link="Orbbec"/>
    <child link="camera_tof_wfov"/>
  </joint>
  <link name="Orbbec">
    <visual>
      <origin xyz="-0.0102186 0.000018 0.0061187" rpy="-1.5707964 0. -1.5707963"/>
      <geometry>
        <mesh filename="../meshes/obj/j2_asm_nano_hold_nano_hold.obj" scale="1. 1. 1."/>
      </geometry>
    </visual>
    <visual>
      <origin xyz="0.0111188 0.004155 0.0024894" rpy="3.1415927 0. 1.5707964"/>
      <geometry>
        <mesh filename="../meshes/obj/nano_core.obj" scale="1. 1. 1."/>
      </geometry>
    </visual>
    <visual>
      <origin xyz="-0.0554185 0.03 -0. " rpy="-1.5707964 0. 0. "/>
      <geometry>
        <mesh filename="../meshes/obj/lens_mc03_solid_solid.obj" scale="1. 1. 1."/>
      </geometry>
    </visual>
    <visual>
      <origin xyz="-0.0605584 -0.0234119 0.0013752" rpy="-0.127409 0. 1.5707964"/>
      <geometry>
        <mesh filename="../meshes/obj/tof_illumination_toro_st_diffuser_toro_st_diffuser.obj" scale="1. 1. 1."/>
      </geometry>
    </visual>
    <visual>
      <origin xyz="-0.0615752 -0.0161131 0.0011876" rpy="0. 0. 1.5707964"/>
      <geometry>
        <mesh filename="../meshes/obj/tof_illumination_toro_lt_diffuser_toro_lt_diffuser.obj" scale="1. 1. 1."/>
      </geometry>
    </visual>
    <visual>
      <origin xyz="-0.0568563 -0.0182209 0.0017673" rpy="-1.5707966 1.4660766 -0.0000003"/>
      <geometry>
        <mesh filename="../meshes/obj/toro_illumination_holder_1_1_1_.obj" scale="1. 1. 1."/>
      </geometry>
    </visual>
    <visual>
      <origin xyz="-0.0575704 -0.0019986 0.001471 " rpy="0. -0.1047198 0. "/>
      <geometry>
        <mesh filename="../meshes/obj/toro_lens_solid_solid.obj" scale="1. 1. 1."/>
      </geometry>
    </visual>
    <visual>
      <origin xyz="0.071706 0.0268993 0.0066857" rpy="-1.5707964 0. -1.5707963"/>
      <geometry>
        <mesh filename="../meshes/obj/port_module_prt0001_prt0001.obj" scale="1. 1. 1."/>
      </geometry>
    </visual>
    <visual>
      <origin xyz="0.0682609 0.0269128 0.0084204" rpy="-1.5707964 0. -1.5707963"/>
      <geometry>
        <mesh filename="../meshes/obj/_x2_4e3b4f53_x0__1_2_1_1_1_1.obj" scale="1. 1. 1."/>
      </geometry>
    </visual>
    <visual>
      <origin xyz="0.0739424 -0.0157 0.0092755" rpy="-1.5707964 0. -1.5707963"/>
      <geometry>
        <mesh filename="../meshes/obj/MicroUSB_solid_solid.obj" scale="1. 1. 1."/>
      </geometry>
    </visual>
    <visual>
      <origin xyz="0.0706791 -0.0018074 0.0102923" rpy="-1.5707964 0. -1.5707963"/>
      <geometry>
        <mesh filename="../meshes/obj/typec_compound_compound.obj" scale="1. 1. 1."/>
      </geometry>
    </visual>
    <visual>
      <origin xyz="0.0735814 -0.003479 0.0088424" rpy="-1.5707964 0. -1.5707963"/>
      <geometry>
        <mesh filename="../meshes/obj/brep_with_voids_brep_with_voids_1285856_brep_with_voids_1285856.obj" scale="1. 1. 1."/>
      </geometry>
    </visual>
    <visual>
      <origin xyz="0.073275 -0.002095 0.00831 " rpy="-1.5707964 0. -1.5707963"/>
      <geometry>
        <mesh filename="../meshes/obj/brep_with_voids_manifold_solid_brep_1286048_manifold_solid_brep_1286048.obj" scale="1. 1. 1."/>
      </geometry>
    </visual>
    <visual>
      <origin xyz="0.073275 -0.001145 0.00831 " rpy="-1.5707964 0. -1.5707963"/>
      <geometry>
        <mesh filename="../meshes/obj/manifold_solid_brep_1154277_1.obj" scale="1. 1. 1."/>
      </geometry>
    </visual>
    <visual>
      <origin xyz="0.0710458 -0.0287344 0.0093983" rpy="-1.5707964 0. -1.5707963"/>
      <geometry>
        <mesh filename="../meshes/obj/dc_power.obj" scale="1. 1. 1."/>
      </geometry>
    </visual>
    <visual>
      <origin xyz="0.0253919 0.0002038 0.0113 " rpy="0. 0. -3.1415925"/>
      <geometry>
        <mesh filename="../meshes/obj/pcb_board.obj" scale="1. 1. 1."/>
      </geometry>
    </visual>
    <visual>
      <origin xyz="-0.00525 -0. 0.0128206" rpy="0. 0. -3.1415925"/>
      <geometry>
        <mesh filename="../meshes/obj/reset_button.obj" scale="1. 1. 1."/>
      </geometry>
    </visual>
    <visual>
      <origin xyz="0.0748378 0.0099992 0.0083182" rpy="-1.5707964 0. 1.5707964"/>
      <geometry>
        <mesh filename="../meshes/obj/sync_port.obj" scale="1. 1. 1."/>
      </geometry>
    </visual>
    <visual>
      <origin xyz="0.0248059 0.0000436 0.0023277" rpy="0. 0. -1.5707964"/>
      <geometry>
        <mesh filename="../meshes/obj/shell_cove.obj" scale="1. 1. 1."/>
      </geometry>
    </visual>
    <visual>
      <origin xyz="-0.0464199 -0.0031039 0.0006303" rpy="0. 0. -1.5707964"/>
      <geometry>
        <mesh filename="../meshes/obj/MegaCover_top_cover_top_cover.obj" scale="1. 1. 1."/>
      </geometry>
    </visual>
    <visual>
      <origin xyz="0.008735 -0.0007389 -0.0036568" rpy="0. 0. -1.5707964"/>
      <geometry>
        <mesh filename="../meshes/obj/MegaCover_bot_cover_bot_cover.obj" scale="1. 1. 1."/>
      </geometry>
    </visual>
    <visual>
      <origin xyz="0.02243 0.0000474 0.0161369" rpy="0. 0. -1.5707964"/>
      <geometry>
        <mesh filename="../meshes/obj/ca.obj" scale="1. 1. 1."/>
      </geometry>
    </visual>
    <visual>
      <origin xyz="-0.0643462 -0.0071227 0.000065 " rpy="0. 0. -1.5707964"/>
      <geometry>
        <mesh filename="../meshes/obj/MegaCover_ldm_lens_ldm_lens.obj" scale="1. 1. 1."/>
      </geometry>
    </visual>
    <visual>
      <origin xyz="-0.0611362 0.0044735 -0.0000379" rpy="0. 0. -1.5707964"/>
      <geometry>
        <mesh filename="../meshes/obj/MegaCover_lens_support_lens_support.obj" scale="1. 1. 1."/>
      </geometry>
    </visual>
    <visual>
      <origin xyz="-0.0643309 0.03 0. " rpy="0. 0. -1.5707964"/>
      <geometry>
        <mesh filename="../meshes/obj/MegaCover_rgb_lens_rgb_lens.obj" scale="1. 1. 1."/>
      </geometry>
    </visual>
    <visual>
      <origin xyz="-0.0643327 -0.002 -0.0005 " rpy="0. 0. -1.5707964"/>
      <geometry>
        <mesh filename="../meshes/obj/MegaCover_ir_lens_ir_lens.obj" scale="1. 1. 1."/>
      </geometry>
    </visual>
    <visual>
      <origin xyz="-0.031825 -0.0091 -0.001 " rpy="0. 0. -1.5707964"/>
      <geometry>
        <mesh filename="../meshes/obj/MegaCover_steel_steel.obj" scale="1. 1. 1."/>
      </geometry>
    </visual>
  </link>
  <link name="camera_rgb"/>
  <link name="camera_tof_nfov"/>
  <link name="camera_tof_wfov"/>


</robot>
