<?xml version="1.0" encoding="UTF-8"?>
<robot name="gbt-c5a_wrist_camera_gripper">
  <joint name="camera_link_joint" type="fixed">
    <origin xyz="0. 0.01325 -0.06997" rpy="-1.2217307 0. 0. "/>
    <parent link="camera_mount_link"/>
    <child link="camera_link"/>
  </joint>
  <joint name="camera_mount_joint" type="fixed">
    <origin xyz="0. 0. 0.012" rpy="1.5707965 0. -3.1415925"/>
    <parent link="GBT_C5A_wrist_camera_gripper_link6"/>
    <child link="camera_mount_link"/>
  </joint>
  <joint name="finger_joint" type="revolute">
    <origin xyz="0. -0.030601 0.054905" rpy="-2.2957964 -0.0000001 -3.1415925"/>
    <parent link="GBT_C5A_wrist_camera_gripper_robotiq_arg2f_base_link"/>
    <child link="left_outer_knuckle"/>
    <axis xyz="1. 0. 0."/>
    <limit lower="0." upper="0.7" effort="1000." velocity="1.9999999"/>
  </joint>
  <joint name="gripper_joint" type="fixed">
    <origin xyz="0. 0.012 -0. " rpy="3.1415925 -1.5707961 1.5707964"/>
    <parent link="camera_mount_link"/>
    <child link="GBT_C5A_wrist_camera_gripper_robotiq_arg2f_base_link"/>
  </joint>
  <joint name="joint1" type="revolute">
    <origin xyz="0. 0. 0.178" rpy="0. 0. 0."/>
    <parent link="GBT_C5A_wrist_camera_gripper_base_link"/>
    <child link="GBT_C5A_wrist_camera_gripper_link1"/>
    <axis xyz="0. 0. 1."/>
    <limit lower="-6.2831853" upper="6.2831853" effort="100." velocity="0.9999999"/>
  </joint>
  <joint name="joint2" type="revolute">
    <origin xyz="0. 0.147 0. " rpy="1.5707964 0. 0. "/>
    <parent link="GBT_C5A_wrist_camera_gripper_link1"/>
    <child link="GBT_C5A_wrist_camera_gripper_link2"/>
    <axis xyz="0. 0. 1."/>
    <limit lower="-1.4835297" upper="4.6251225" effort="100." velocity="0.9999999"/>
  </joint>
  <joint name="joint3" type="revolute">
    <origin xyz="0.425 -0. 0.072" rpy="0. 0. 0."/>
    <parent link="GBT_C5A_wrist_camera_gripper_link2"/>
    <child link="GBT_C5A_wrist_camera_gripper_link3"/>
    <axis xyz="0. 0. 1."/>
    <limit lower="-2.879793" upper="2.879793" effort="100." velocity="0.9999999"/>
  </joint>
  <joint name="joint4" type="revolute">
    <origin xyz="0.385 0. -0.052" rpy="0. 0. 0."/>
    <parent link="GBT_C5A_wrist_camera_gripper_link3"/>
    <child link="GBT_C5A_wrist_camera_gripper_link4"/>
    <axis xyz="0. 0. 1."/>
    <limit lower="-1.4835297" upper="4.6251225" effort="100." velocity="0.9999999"/>
  </joint>
  <joint name="joint5" type="revolute">
    <origin xyz="-0. -0.1233 0. " rpy="1.5707964 0. 0. "/>
    <parent link="GBT_C5A_wrist_camera_gripper_link4"/>
    <child link="GBT_C5A_wrist_camera_gripper_link5"/>
    <axis xyz="0. 0. 1."/>
    <limit lower="-6.2831853" upper="6.2831853" effort="100." velocity="0.9999999"/>
  </joint>
  <joint name="joint6" type="revolute">
    <origin xyz="0. -0.1003 -0. " rpy="1.5707963 0. 0. "/>
    <parent link="GBT_C5A_wrist_camera_gripper_link5"/>
    <child link="GBT_C5A_wrist_camera_gripper_link6"/>
    <axis xyz="0. 0. 1."/>
    <limit lower="-6.2831853" upper="6.2831853" effort="100." velocity="0.9999999"/>
  </joint>
  <joint name="joint_camera_link-Stream_depth" type="fixed">
    <origin xyz="-0.025 -0. 0.0061397" rpy="-3.1415925 0. -3.1415927"/>
    <parent link="camera_link"/>
    <child link="Stream_depth"/>
  </joint>
  <joint name="joint_camera_link-Stream_ir_left" type="fixed">
    <origin xyz="-0.025 -0. 0.0061397" rpy="-3.1415925 0. -3.1415927"/>
    <parent link="camera_link"/>
    <child link="Stream_ir_left"/>
  </joint>
  <joint name="joint_camera_link-Stream_ir_right" type="fixed">
    <origin xyz="0.025 -0.0000002 0.0061398" rpy="-3.1415925 0. -3.1415927"/>
    <parent link="camera_link"/>
    <child link="Stream_ir_right"/>
  </joint>
  <joint name="joint_camera_link-Stream_rgb" type="fixed">
    <origin xyz="0.010989 -0.0000077 0.0076121" rpy="-3.1415925 0. -3.1415927"/>
    <parent link="camera_link"/>
    <child link="Stream_rgb"/>
  </joint>
  <joint name="joint_Stream_depth-viewport_mesh" type="fixed">
    <origin xyz="0. 0. 0." rpy="0. 0. 0."/>
    <parent link="Stream_depth"/>
    <child link="Stream_depth_OmniverseKitViewportCameraMesh"/>
  </joint>
  <joint name="joint_Stream_ir_left-viewport_mesh" type="fixed">
    <origin xyz="0. 0. 0." rpy="0. 0. 0."/>
    <parent link="Stream_ir_left"/>
    <child link="Stream_ir_left_OmniverseKitViewportCameraMesh"/>
  </joint>
  <joint name="joint_Stream_ir_right-viewport_mesh" type="fixed">
    <origin xyz="0. 0. 0." rpy="0. 0. 0."/>
    <parent link="Stream_ir_right"/>
    <child link="Stream_ir_right_OmniverseKitViewportCameraMesh"/>
  </joint>
  <joint name="joint_Stream_rgb-viewport_mesh" type="fixed">
    <origin xyz="0. 0. 0." rpy="0. 0. 0."/>
    <parent link="Stream_rgb"/>
    <child link="Stream_rgb_OmniverseKitViewportCameraMesh"/>
  </joint>
  <joint name="left_inner_finger_joint" type="revolute">
    <origin xyz="-0. 0.0817554 -0.0282204" rpy="-0.725 0. 0. "/>
    <parent link="left_outer_finger"/>
    <child link="left_inner_finger"/>
    <axis xyz="1. 0. 0."/>
    <limit lower="-0.14" upper="0.84" effort="0." velocity="17453.2925199"/>
  </joint>
  <joint name="left_inner_finger_pad_joint" type="fixed">
    <origin xyz="-0. 0.0457553 -0.0272204" rpy="-0.0000001 -0. -0.0000001"/>
    <parent link="left_inner_finger"/>
    <child link="left_inner_finger_pad"/>
  </joint>
  <joint name="left_inner_knuckle_joint" type="revolute">
    <origin xyz="0. -0.0127 0.06142" rpy="2.2957964 0.0000001 0.0000002"/>
    <parent link="GBT_C5A_wrist_camera_gripper_robotiq_arg2f_base_link"/>
    <child link="left_inner_knuckle"/>
    <axis xyz="1. 0. 0."/>
    <limit lower="-0.84" upper="0.14" effort="0." velocity="17453.2925199"/>
  </joint>
  <joint name="left_outer_finger_joint" type="fixed">
    <origin xyz="-0. -0.01822 0.0260018" rpy="0.0000002 0.0000002 -3.1415925"/>
    <parent link="left_outer_knuckle"/>
    <child link="left_outer_finger"/>
  </joint>
  <joint name="right_inner_finger_joint" type="revolute">
    <origin xyz="0. 0.0817554 -0.0282204" rpy="-0.725 0. 0. "/>
    <parent link="right_outer_finger"/>
    <child link="right_inner_finger"/>
    <axis xyz="1. 0. 0."/>
    <limit lower="-0.14" upper="0.84" effort="0." velocity="17453.2925199"/>
  </joint>
  <joint name="right_inner_finger_pad_joint" type="fixed">
    <origin xyz="0. 0.0457553 -0.0272204" rpy="-0.0000001 -0. 0.0000001"/>
    <parent link="right_inner_finger"/>
    <child link="right_inner_finger_pad"/>
  </joint>
  <joint name="right_inner_knuckle_joint" type="revolute">
    <origin xyz="0. 0.0127 0.06142" rpy="2.2957966 -0.0000001 -3.1415925"/>
    <parent link="GBT_C5A_wrist_camera_gripper_robotiq_arg2f_base_link"/>
    <child link="right_inner_knuckle"/>
    <axis xyz="1. 0. 0."/>
    <limit lower="-0.84" upper="0.14" effort="0." velocity="17453.2925199"/>
  </joint>
  <joint name="right_outer_finger_joint" type="fixed">
    <origin xyz="-0. 0.0182199 0.0260018" rpy="-0.0000001 -0.0000004 0.0000001"/>
    <parent link="right_outer_knuckle"/>
    <child link="right_outer_finger"/>
  </joint>
  <joint name="right_outer_knuckle_joint" type="revolute">
    <origin xyz="0. 0.030601 0.054905" rpy="2.2957966 -0.0000001 -3.1415925"/>
    <parent link="GBT_C5A_wrist_camera_gripper_robotiq_arg2f_base_link"/>
    <child link="right_outer_knuckle"/>
    <axis xyz="1. 0. 0."/>
    <limit lower="-0.84" upper="0.14" effort="0." velocity="17453.2925199"/>
  </joint>
  <joint name="root_joint" type="fixed">
    <origin xyz="0. 0. 0." rpy="0. 0. 0."/>
    <parent link="GBT_C5A_wrist_camera_gripper"/>
    <child link="GBT_C5A_wrist_camera_gripper_base_link"/>
  </joint>
  <joint name="tcp_joint" type="fixed">
    <origin xyz="0. 0. 0.234" rpy="-0.0000001 0.0000001 0.0000002"/>
    <parent link="GBT_C5A_wrist_camera_gripper_robotiq_arg2f_base_link"/>
    <child link="tcp"/>
  </joint>
  <link name="GBT_C5A_wrist_camera_gripper"/>
  <link name="GBT_C5A_wrist_camera_gripper_base_link">
    <inertial>
      <origin xyz="-0.000115 -0.003836 0.044852" rpy="0. 0. 0."/>
      <mass value="1.489536"/>
      <inertia ixx="0.004543" ixy="-0.000001" ixz="-0.000011" iyy="0.003119" iyz="0.000197" izz="0.0058"/>
    </inertial>
    <visual>
      <origin xyz="0. 0. 0." rpy="0. 0. 0."/>
      <geometry>
        <mesh filename="file:///home/gbt/ws/urdf/gbt-c5a_wrist_camera_gripper/meshes/GBT_C5A_wrist_camera_gripper_base_link_visuals_base_link_World_mesh.obj" scale="1. 1. 1."/>
      </geometry>
    </visual>
    <visual>
      <origin xyz="0. 0. 0." rpy="0. 0. 0."/>
      <geometry>
        <mesh filename="file:///home/gbt/ws/urdf/gbt-c5a_wrist_camera_gripper/meshes/GBT_C5A_wrist_camera_gripper_base_link_collisions_base_link_node_STL_BINARY__mesh.obj" scale="1. 1. 1."/>
      </geometry>
    </visual>
    <collision>
      <origin xyz="0. 0. 0." rpy="0. 0. 0."/>
      <geometry>
        <mesh filename="file:///home/gbt/ws/urdf/gbt-c5a_wrist_camera_gripper/meshes/GBT_C5A_wrist_camera_gripper_base_link_collisions_base_link_node_STL_BINARY__mesh.obj" scale="1. 1. 1."/>
      </geometry>
    </collision>
  </link>
  <link name="GBT_C5A_wrist_camera_gripper_link1">
    <inertial>
      <origin xyz="-0.000366 0.00196 -0.027035" rpy="0. 0. 0."/>
      <mass value="4.7630582"/>
      <inertia ixx="0.010679" ixy="0.00004" ixz="-0.000058" iyy="0.010619" iyz="0.000214" izz="0.008154"/>
    </inertial>
    <visual>
      <origin xyz="0. 0. 0." rpy="0. 0. 0."/>
      <geometry>
        <mesh filename="file:///home/gbt/ws/urdf/gbt-c5a_wrist_camera_gripper/meshes/GBT_C5A_wrist_camera_gripper_link1_visuals_link1_World_mesh.obj" scale="1. 1. 1."/>
      </geometry>
    </visual>
    <visual>
      <origin xyz="0. 0. 0." rpy="0. 0. 0."/>
      <geometry>
        <mesh filename="file:///home/gbt/ws/urdf/gbt-c5a_wrist_camera_gripper/meshes/GBT_C5A_wrist_camera_gripper_link1_collisions_link1_node_STL_BINARY__mesh.obj" scale="1. 1. 1."/>
      </geometry>
    </visual>
    <collision>
      <origin xyz="0. 0. 0." rpy="0. 0. 0."/>
      <geometry>
        <mesh filename="file:///home/gbt/ws/urdf/gbt-c5a_wrist_camera_gripper/meshes/GBT_C5A_wrist_camera_gripper_link1_collisions_link1_node_STL_BINARY__mesh.obj" scale="1. 1. 1."/>
      </geometry>
    </collision>
  </link>
  <link name="GBT_C5A_wrist_camera_gripper_link2">
    <inertial>
      <origin xyz="0.212421 0. 0.023494" rpy="0. 0. 0."/>
      <mass value="10.9228296"/>
      <inertia ixx="0.025117" ixy="0.000815" ixz="0.000075" iyy="0.463693" iyz="0.000001" izz="0.457686"/>
    </inertial>
    <visual>
      <origin xyz="0. 0. 0." rpy="0. 0. 0."/>
      <geometry>
        <mesh filename="file:///home/gbt/ws/urdf/gbt-c5a_wrist_camera_gripper/meshes/GBT_C5A_wrist_camera_gripper_link2_visuals_link2_World_mesh.obj" scale="1. 1. 1."/>
      </geometry>
    </visual>
    <visual>
      <origin xyz="0. 0. 0." rpy="0. 0. 0."/>
      <geometry>
        <mesh filename="file:///home/gbt/ws/urdf/gbt-c5a_wrist_camera_gripper/meshes/GBT_C5A_wrist_camera_gripper_link2_collisions_link2_node_STL_BINARY__mesh.obj" scale="1. 1. 1."/>
      </geometry>
    </visual>
    <collision>
      <origin xyz="0. 0. 0." rpy="0. 0. 0."/>
      <geometry>
        <mesh filename="file:///home/gbt/ws/urdf/gbt-c5a_wrist_camera_gripper/meshes/GBT_C5A_wrist_camera_gripper_link2_collisions_link2_node_STL_BINARY__mesh.obj" scale="1. 1. 1."/>
      </geometry>
    </collision>
  </link>
  <link name="GBT_C5A_wrist_camera_gripper_link3">
    <inertial>
      <origin xyz="0.240843 -0.000259 0.057044" rpy="0. 0. 0."/>
      <mass value="3.817807"/>
      <inertia ixx="0.006786" ixy="-0.000147" ixz="-0.001424" iyy="0.104226" iyz="-0.000012" izz="0.102926"/>
    </inertial>
    <visual>
      <origin xyz="-0. 0. -0." rpy="0. 0. 0."/>
      <geometry>
        <mesh filename="file:///home/gbt/ws/urdf/gbt-c5a_wrist_camera_gripper/meshes/GBT_C5A_wrist_camera_gripper_link3_visuals_link3_World_mesh.obj" scale="1. 1. 1."/>
      </geometry>
    </visual>
    <visual>
      <origin xyz="-0. 0. -0." rpy="0. 0. 0."/>
      <geometry>
        <mesh filename="file:///home/gbt/ws/urdf/gbt-c5a_wrist_camera_gripper/meshes/GBT_C5A_wrist_camera_gripper_link3_collisions_link3_node_STL_BINARY__mesh.obj" scale="1. 1. 1."/>
      </geometry>
    </visual>
    <collision>
      <origin xyz="-0. 0. -0." rpy="0. 0. 0."/>
      <geometry>
        <mesh filename="file:///home/gbt/ws/urdf/gbt-c5a_wrist_camera_gripper/meshes/GBT_C5A_wrist_camera_gripper_link3_collisions_link3_node_STL_BINARY__mesh.obj" scale="1. 1. 1."/>
      </geometry>
    </collision>
  </link>
  <link name="GBT_C5A_wrist_camera_gripper_link4">
    <inertial>
      <origin xyz="0.000527 -0.017542 -0.002802" rpy="0. 0. 0."/>
      <mass value="1.860492"/>
      <inertia ixx="0.003113" ixy="0.000018" ixz="-0.000009" iyy="0.01678" iyz="0.000064" izz="0.002995"/>
    </inertial>
    <visual>
      <origin xyz="-0. -0. 0." rpy="0. 0. 0."/>
      <geometry>
        <mesh filename="file:///home/gbt/ws/urdf/gbt-c5a_wrist_camera_gripper/meshes/GBT_C5A_wrist_camera_gripper_link4_visuals_link4_World_mesh.obj" scale="1. 1. 1."/>
      </geometry>
    </visual>
    <visual>
      <origin xyz="-0. -0. 0." rpy="0. 0. 0."/>
      <geometry>
        <mesh filename="file:///home/gbt/ws/urdf/gbt-c5a_wrist_camera_gripper/meshes/GBT_C5A_wrist_camera_gripper_link4_collisions_link4_node_STL_BINARY__mesh.obj" scale="1. 1. 1."/>
      </geometry>
    </visual>
    <collision>
      <origin xyz="-0. -0. 0." rpy="0. 0. 0."/>
      <geometry>
        <mesh filename="file:///home/gbt/ws/urdf/gbt-c5a_wrist_camera_gripper/meshes/GBT_C5A_wrist_camera_gripper_link4_collisions_link4_node_STL_BINARY__mesh.obj" scale="1. 1. 1."/>
      </geometry>
    </collision>
  </link>
  <link name="GBT_C5A_wrist_camera_gripper_link5">
    <inertial>
      <origin xyz="-0.000539 -0.018034 -0.003263" rpy="0. 0. 0."/>
      <mass value="1.823601"/>
      <inertia ixx="0.003117" ixy="-0.000019" ixz="-0.000008" iyy="0.0159" iyz="-0.000099" izz="0.003001"/>
    </inertial>
    <visual>
      <origin xyz="0. 0. -0." rpy="-0. 0. 0."/>
      <geometry>
        <mesh filename="file:///home/gbt/ws/urdf/gbt-c5a_wrist_camera_gripper/meshes/GBT_C5A_wrist_camera_gripper_link5_visuals_link5_World_mesh.obj" scale="1. 1. 1."/>
      </geometry>
    </visual>
    <visual>
      <origin xyz="0. 0. -0." rpy="-0. 0. 0."/>
      <geometry>
        <mesh filename="file:///home/gbt/ws/urdf/gbt-c5a_wrist_camera_gripper/meshes/GBT_C5A_wrist_camera_gripper_link5_collisions_link5_node_STL_BINARY__mesh.obj" scale="1. 1. 1."/>
      </geometry>
    </visual>
    <collision>
      <origin xyz="0. 0. -0." rpy="-0. 0. 0."/>
      <geometry>
        <mesh filename="file:///home/gbt/ws/urdf/gbt-c5a_wrist_camera_gripper/meshes/GBT_C5A_wrist_camera_gripper_link5_collisions_link5_node_STL_BINARY__mesh.obj" scale="1. 1. 1."/>
      </geometry>
    </collision>
  </link>
  <link name="GBT_C5A_wrist_camera_gripper_link6">
    <inertial>
      <origin xyz="-0.000012 -0.000333 -0.014577" rpy="0. 0. 0."/>
      <mass value="0.240531"/>
      <inertia ixx="0.000135" ixy="0." ixz="0." iyy="0.000132" iyz="0." izz="0.000234"/>
    </inertial>
    <visual>
      <origin xyz="0. 0. 0." rpy="-0.0000002 0. 0. "/>
      <geometry>
        <mesh filename="file:///home/gbt/ws/urdf/gbt-c5a_wrist_camera_gripper/meshes/GBT_C5A_wrist_camera_gripper_link6_visuals_link6_World_mesh.obj" scale="1. 1. 1."/>
      </geometry>
    </visual>
    <visual>
      <origin xyz="0. 0. 0." rpy="-0.0000002 0. 0. "/>
      <geometry>
        <mesh filename="file:///home/gbt/ws/urdf/gbt-c5a_wrist_camera_gripper/meshes/GBT_C5A_wrist_camera_gripper_link6_collisions_link6_node_STL_BINARY__mesh.obj" scale="1. 1. 1."/>
      </geometry>
    </visual>
    <collision>
      <origin xyz="0. 0. 0." rpy="-0.0000002 0. 0. "/>
      <geometry>
        <mesh filename="file:///home/gbt/ws/urdf/gbt-c5a_wrist_camera_gripper/meshes/GBT_C5A_wrist_camera_gripper_link6_collisions_link6_node_STL_BINARY__mesh.obj" scale="1. 1. 1."/>
      </geometry>
    </collision>
  </link>
  <link name="GBT_C5A_wrist_camera_gripper_robotiq_arg2f_base_link">
    <inertial>
      <origin xyz="0.0000001 -0.0000047 0.03145 " rpy="0. 0. 0."/>
      <mass value="0.22652"/>
      <inertia ixx="0.0002" ixy="-0." ixz="-0." iyy="0.0001783" iyz="-0." izz="0.0001348"/>
    </inertial>
    <visual>
      <origin xyz="0. 0. -0." rpy="-0.0000001 0.0000001 0.0000002"/>
      <geometry>
        <mesh filename="file:///home/gbt/ws/urdf/gbt-c5a_wrist_camera_gripper/meshes/GBT_C5A_wrist_camera_gripper_robotiq_arg2f_base_link_visuals_robotiq_arg2f_base_link_node_STL_BINARY__mesh.obj" scale="1. 1. 1."/>
      </geometry>
    </visual>
    <visual>
      <origin xyz="0. 0. -0." rpy="-0.0000001 0.0000001 0.0000002"/>
      <geometry>
        <mesh filename="file:///home/gbt/ws/urdf/gbt-c5a_wrist_camera_gripper/meshes/GBT_C5A_wrist_camera_gripper_robotiq_arg2f_base_link_collisions_robotiq_arg2f_base_link_node_STL_BINARY__mesh.obj" scale="1. 1. 1."/>
      </geometry>
    </visual>
    <collision>
      <origin xyz="0. 0. -0." rpy="-0.0000001 0.0000001 0.0000002"/>
      <geometry>
        <mesh filename="file:///home/gbt/ws/urdf/gbt-c5a_wrist_camera_gripper/meshes/GBT_C5A_wrist_camera_gripper_robotiq_arg2f_base_link_collisions_robotiq_arg2f_base_link_node_STL_BINARY__mesh.obj" scale="1. 1. 1."/>
      </geometry>
    </collision>
  </link>
  <link name="Stream_depth"/>
  <link name="Stream_depth_OmniverseKitViewportCameraMesh"/>
  <link name="Stream_ir_left"/>
  <link name="Stream_ir_left_OmniverseKitViewportCameraMesh"/>
  <link name="Stream_ir_right"/>
  <link name="Stream_ir_right_OmniverseKitViewportCameraMesh"/>
  <link name="Stream_rgb"/>
  <link name="Stream_rgb_OmniverseKitViewportCameraMesh"/>
  <link name="camera_link">
    <inertial>
      <origin xyz="0. 0. 0." rpy="0. 0. 0."/>
      <mass value="1."/>
      <inertia ixx="0.0001" ixy="0." ixz="0." iyy="0.0001" iyz="0." izz="0.0001"/>
    </inertial>
    <visual>
      <origin xyz="-0.0000628 0.0000002 0.0108373" rpy="-0. 0. 0."/>
      <geometry>
        <mesh filename="file:///home/gbt/ws/urdf/gbt-c5a_wrist_camera_gripper/meshes/front_cover_solid_solid.obj" scale="1. 1. 1."/>
      </geometry>
    </visual>
    <visual>
      <origin xyz="-0.0000103 -0.0000072 0.0078066" rpy="-0. 0. 0."/>
      <geometry>
        <mesh filename="file:///home/gbt/ws/urdf/gbt-c5a_wrist_camera_gripper/meshes/Orbbec_Gemini2_camera_ldm_camera_ldm.obj" scale="1. 1. 1."/>
      </geometry>
    </visual>
    <visual>
      <origin xyz="0.010989 -0.0000077 0.0076121" rpy="-0. 0. 0."/>
      <geometry>
        <mesh filename="file:///home/gbt/ws/urdf/gbt-c5a_wrist_camera_gripper/meshes/Orbbec_Gemini2_camera_rgb_camera_rgb.obj" scale="1. 1. 1."/>
      </geometry>
    </visual>
    <visual>
      <origin xyz="0.0000232 0.0004161 0.0011014" rpy="-0. 0. 0."/>
      <geometry>
        <mesh filename="file:///home/gbt/ws/urdf/gbt-c5a_wrist_camera_gripper/meshes/Orbbec_Gemini2_gemini2_body_gemini2_body.obj" scale="1. 1. 1."/>
      </geometry>
    </visual>
    <visual>
      <origin xyz="-0.0000042 0.0000468 -0.0149367" rpy="-0. 0. 0."/>
      <geometry>
        <mesh filename="file:///home/gbt/ws/urdf/gbt-c5a_wrist_camera_gripper/meshes/Orbbec_Gemini2_back_cover_back_cover.obj" scale="1. 1. 1."/>
      </geometry>
    </visual>
    <visual>
      <origin xyz="0.0175 -0.0115044 0.0006957" rpy="-0. 0. 0."/>
      <geometry>
        <mesh filename="file:///home/gbt/ws/urdf/gbt-c5a_wrist_camera_gripper/meshes/foot_left.obj" scale="1. 1. 1."/>
      </geometry>
    </visual>
    <visual>
      <origin xyz="-0.0175 -0.0115044 0.0006957" rpy="-0. 0. 0."/>
      <geometry>
        <mesh filename="file:///home/gbt/ws/urdf/gbt-c5a_wrist_camera_gripper/meshes/foot_right.obj" scale="1. 1. 1."/>
      </geometry>
    </visual>
    <visual>
      <origin xyz="-0.025 -0. 0.0061397" rpy="-0. 0. 0."/>
      <geometry>
        <mesh filename="file:///home/gbt/ws/urdf/gbt-c5a_wrist_camera_gripper/meshes/camera_left.obj" scale="1. 1. 1."/>
      </geometry>
    </visual>
    <visual>
      <origin xyz="0.025 -0.0000002 0.0061398" rpy="-0. 0. 0."/>
      <geometry>
        <mesh filename="file:///home/gbt/ws/urdf/gbt-c5a_wrist_camera_gripper/meshes/camera_right.obj" scale="1. 1. 1."/>
      </geometry>
    </visual>
  </link>
  <link name="camera_mount_link">
    <inertial>
      <origin xyz="0. 0. 0.003" rpy="0. 0. 0."/>
      <mass value="0.16"/>
      <inertia ixx="0.0001" ixy="0." ixz="0." iyy="0.0001" iyz="0." izz="0.0001"/>
    </inertial>
    <visual>
      <origin xyz="0. -0. 0." rpy="-1.5707966 0. 0. "/>
      <geometry>
        <mesh filename="file:///home/gbt/ws/urdf/gbt-c5a_wrist_camera_gripper/meshes/camera_mount_link_visuals_camera_mount_World_mesh.obj" scale="1. 1. 1."/>
      </geometry>
    </visual>
    <visual>
      <origin xyz="0. -0. 0." rpy="-1.5707966 0. 0. "/>
      <geometry>
        <mesh filename="file:///home/gbt/ws/urdf/gbt-c5a_wrist_camera_gripper/meshes/camera_mount_link_collisions_camera_mount_node_STL_BINARY__mesh.obj" scale="1. 1. 1."/>
      </geometry>
    </visual>
    <collision>
      <origin xyz="0. -0. 0." rpy="-1.5707966 0. 0. "/>
      <geometry>
        <mesh filename="file:///home/gbt/ws/urdf/gbt-c5a_wrist_camera_gripper/meshes/camera_mount_link_collisions_camera_mount_node_STL_BINARY__mesh.obj" scale="1. 1. 1."/>
      </geometry>
    </collision>
  </link>
  <link name="left_inner_finger">
    <inertial>
      <origin xyz="0.0003 0.0160078 -0.0136946" rpy="0. 0. 0."/>
      <mass value="0.0104003"/>
      <inertia ixx="0.0000027" ixy="0." ixz="0." iyy="0.0000008" iyz="0.0000007" izz="0.0000023"/>
    </inertial>
    <visual>
      <origin xyz="-0. -0.0000001 -0. " rpy="-0.0000001 -0. -0.0000001"/>
      <geometry>
        <mesh filename="file:///home/gbt/ws/urdf/gbt-c5a_wrist_camera_gripper/meshes/left_inner_finger_visuals_robotiq_arg2f_140_inner_finger_node_STL_BINARY__mesh.obj" scale="1. 1. 1."/>
      </geometry>
    </visual>
    <visual>
      <origin xyz="-0. -0.0000001 -0. " rpy="-0.0000001 -0. -0.0000001"/>
      <geometry>
        <mesh filename="file:///home/gbt/ws/urdf/gbt-c5a_wrist_camera_gripper/meshes/left_inner_finger_collisions_robotiq_arg2f_140_inner_finger_node_STL_BINARY__mesh.obj" scale="1. 1. 1."/>
      </geometry>
    </visual>
    <collision>
      <origin xyz="-0. -0.0000001 -0. " rpy="-0.0000001 -0. -0.0000001"/>
      <geometry>
        <mesh filename="file:///home/gbt/ws/urdf/gbt-c5a_wrist_camera_gripper/meshes/left_inner_finger_collisions_robotiq_arg2f_140_inner_finger_node_STL_BINARY__mesh.obj" scale="1. 1. 1."/>
      </geometry>
    </collision>
  </link>
  <link name="left_inner_finger_pad">
    <inertial>
      <origin xyz="0. 0. 0." rpy="0. 0. 0."/>
      <mass value="0.01575"/>
      <inertia ixx="0.0000065" ixy="0." ixz="0." iyy="0.0000013" iyz="0." izz="0.0000076"/>
    </inertial>
    <visual>
      <origin xyz="0. -0. 0." rpy="0. 0. 0."/>
      <geometry>
        <box size="0.027 0.065 0.0075"/>
      </geometry>
    </visual>
    <visual>
      <origin xyz="0. -0. 0." rpy="0. 0. 0."/>
      <geometry>
        <box size="0.03 0.07 0.0075"/>
      </geometry>
    </visual>
    <collision>
      <origin xyz="0. -0. 0." rpy="0. 0. 0."/>
      <geometry>
        <box size="0.03 0.07 0.0075"/>
      </geometry>
    </collision>
  </link>
  <link name="left_inner_knuckle">
    <inertial>
      <origin xyz="0.000123 0.0507851 0.0010397" rpy="0. 0. 0."/>
      <mass value="0.0271177"/>
      <inertia ixx="0.0000262" ixy="-0.0000002" ixz="-0." iyy="0.0000028" iyz="-0.0000005" izz="0.0000284"/>
    </inertial>
    <visual>
      <origin xyz="0. 0. 0." rpy="0.0000002 0.0000002 0. "/>
      <geometry>
        <mesh filename="file:///home/gbt/ws/urdf/gbt-c5a_wrist_camera_gripper/meshes/left_inner_knuckle_visuals_robotiq_arg2f_140_inner_knuckle_node_STL_BINARY__mesh.obj" scale="1. 1. 1."/>
      </geometry>
    </visual>
    <visual>
      <origin xyz="0. 0. 0." rpy="0.0000002 0.0000002 0. "/>
      <geometry>
        <mesh filename="file:///home/gbt/ws/urdf/gbt-c5a_wrist_camera_gripper/meshes/left_inner_knuckle_collisions_robotiq_arg2f_140_inner_knuckle_node_STL_BINARY__mesh.obj" scale="1. 1. 1."/>
      </geometry>
    </visual>
    <collision>
      <origin xyz="0. 0. 0." rpy="0.0000002 0.0000002 0. "/>
      <geometry>
        <mesh filename="file:///home/gbt/ws/urdf/gbt-c5a_wrist_camera_gripper/meshes/left_inner_knuckle_collisions_robotiq_arg2f_140_inner_knuckle_node_STL_BINARY__mesh.obj" scale="1. 1. 1."/>
      </geometry>
    </collision>
  </link>
  <link name="left_outer_finger">
    <inertial>
      <origin xyz="0.0003012 0.0373908 -0.0208027" rpy="0. 0. 0."/>
      <mass value="0.0226142"/>
      <inertia ixx="0.0000153" ixy="0." ixz="-0." iyy="0.0000062" iyz="0.0000068" izz="0.0000116"/>
    </inertial>
    <visual>
      <origin xyz="-0. -0. -0." rpy="0. 0. 0."/>
      <geometry>
        <mesh filename="file:///home/gbt/ws/urdf/gbt-c5a_wrist_camera_gripper/meshes/left_outer_finger_visuals_robotiq_arg2f_140_outer_finger_node_STL_BINARY__mesh.obj" scale="1. 1. 1."/>
      </geometry>
    </visual>
    <visual>
      <origin xyz="-0. -0. -0." rpy="0. 0. 0."/>
      <geometry>
        <mesh filename="file:///home/gbt/ws/urdf/gbt-c5a_wrist_camera_gripper/meshes/left_outer_finger_collisions_robotiq_arg2f_140_outer_finger_node_STL_BINARY__mesh.obj" scale="1. 1. 1."/>
      </geometry>
    </visual>
    <collision>
      <origin xyz="-0. -0. -0." rpy="0. 0. 0."/>
      <geometry>
        <mesh filename="file:///home/gbt/ws/urdf/gbt-c5a_wrist_camera_gripper/meshes/left_outer_finger_collisions_robotiq_arg2f_140_outer_finger_node_STL_BINARY__mesh.obj" scale="1. 1. 1."/>
      </geometry>
    </collision>
  </link>
  <link name="left_outer_knuckle">
    <inertial>
      <origin xyz="-0.0002 0.0199436 0.0292245" rpy="0. 0. 0."/>
      <mass value="0.008532"/>
      <inertia ixx="0.0000029" ixy="0." ixz="0." iyy="0.0000019" iyz="-0.0000012" izz="0.0000012"/>
    </inertial>
    <visual>
      <origin xyz="-0. 0. -0." rpy="0.0000002 0.0000002 -3.1415925"/>
      <geometry>
        <mesh filename="file:///home/gbt/ws/urdf/gbt-c5a_wrist_camera_gripper/meshes/left_outer_knuckle_visuals_robotiq_arg2f_140_outer_knuckle_node_STL_BINARY__mesh.obj" scale="1. 1. 1."/>
      </geometry>
    </visual>
    <visual>
      <origin xyz="-0. 0. -0." rpy="0.0000002 0.0000002 -3.1415925"/>
      <geometry>
        <mesh filename="file:///home/gbt/ws/urdf/gbt-c5a_wrist_camera_gripper/meshes/left_outer_knuckle_collisions_robotiq_arg2f_140_outer_knuckle_node_STL_BINARY__mesh.obj" scale="1. 1. 1."/>
      </geometry>
    </visual>
    <collision>
      <origin xyz="-0. 0. -0." rpy="0.0000002 0.0000002 -3.1415925"/>
      <geometry>
        <mesh filename="file:///home/gbt/ws/urdf/gbt-c5a_wrist_camera_gripper/meshes/left_outer_knuckle_collisions_robotiq_arg2f_140_outer_knuckle_node_STL_BINARY__mesh.obj" scale="1. 1. 1."/>
      </geometry>
    </collision>
  </link>
  <link name="right_inner_finger">
    <inertial>
      <origin xyz="0.0003 0.0160078 -0.0136946" rpy="0. 0. 0."/>
      <mass value="0.0104003"/>
      <inertia ixx="0.0000027" ixy="0." ixz="0." iyy="0.0000008" iyz="0.0000007" izz="0.0000023"/>
    </inertial>
    <visual>
      <origin xyz="0. -0.0000001 -0. " rpy="-0.0000001 -0. 0.0000001"/>
      <geometry>
        <mesh filename="file:///home/gbt/ws/urdf/gbt-c5a_wrist_camera_gripper/meshes/right_inner_finger_visuals_robotiq_arg2f_140_inner_finger_node_STL_BINARY__mesh.obj" scale="1. 1. 1."/>
      </geometry>
    </visual>
    <visual>
      <origin xyz="0. -0.0000001 -0. " rpy="-0.0000001 -0. 0.0000001"/>
      <geometry>
        <mesh filename="file:///home/gbt/ws/urdf/gbt-c5a_wrist_camera_gripper/meshes/right_inner_finger_collisions_robotiq_arg2f_140_inner_finger_node_STL_BINARY__mesh.obj" scale="1. 1. 1."/>
      </geometry>
    </visual>
    <collision>
      <origin xyz="0. -0.0000001 -0. " rpy="-0.0000001 -0. 0.0000001"/>
      <geometry>
        <mesh filename="file:///home/gbt/ws/urdf/gbt-c5a_wrist_camera_gripper/meshes/right_inner_finger_collisions_robotiq_arg2f_140_inner_finger_node_STL_BINARY__mesh.obj" scale="1. 1. 1."/>
      </geometry>
    </collision>
  </link>
  <link name="right_inner_finger_pad">
    <inertial>
      <origin xyz="0. 0. 0." rpy="0. 0. 0."/>
      <mass value="0.01575"/>
      <inertia ixx="0.0000065" ixy="0." ixz="0." iyy="0.0000013" iyz="0." izz="0.0000076"/>
    </inertial>
    <visual>
      <origin xyz="-0. -0. 0." rpy="0. 0. 0."/>
      <geometry>
        <box size="0.027 0.065 0.0075"/>
      </geometry>
    </visual>
    <visual>
      <origin xyz="-0. -0. 0." rpy="0. 0. 0."/>
      <geometry>
        <box size="0.03 0.07 0.0075"/>
      </geometry>
    </visual>
    <collision>
      <origin xyz="-0. -0. 0." rpy="0. 0. 0."/>
      <geometry>
        <box size="0.03 0.07 0.0075"/>
      </geometry>
    </collision>
  </link>
  <link name="right_inner_knuckle">
    <inertial>
      <origin xyz="0.000123 0.0507851 0.0010397" rpy="0. 0. 0."/>
      <mass value="0.0271177"/>
      <inertia ixx="0.0000262" ixy="-0.0000002" ixz="-0." iyy="0.0000028" iyz="-0.0000005" izz="0.0000284"/>
    </inertial>
    <visual>
      <origin xyz="-0. -0. 0." rpy="0. -0.0000005 0.0000001"/>
      <geometry>
        <mesh filename="file:///home/gbt/ws/urdf/gbt-c5a_wrist_camera_gripper/meshes/right_inner_knuckle_visuals_robotiq_arg2f_140_inner_knuckle_node_STL_BINARY__mesh.obj" scale="1. 1. 1."/>
      </geometry>
    </visual>
    <visual>
      <origin xyz="-0. -0. 0." rpy="0. -0.0000005 0.0000001"/>
      <geometry>
        <mesh filename="file:///home/gbt/ws/urdf/gbt-c5a_wrist_camera_gripper/meshes/right_inner_knuckle_collisions_robotiq_arg2f_140_inner_knuckle_node_STL_BINARY__mesh.obj" scale="1. 1. 1."/>
      </geometry>
    </visual>
    <collision>
      <origin xyz="-0. -0. 0." rpy="0. -0.0000005 0.0000001"/>
      <geometry>
        <mesh filename="file:///home/gbt/ws/urdf/gbt-c5a_wrist_camera_gripper/meshes/right_inner_knuckle_collisions_robotiq_arg2f_140_inner_knuckle_node_STL_BINARY__mesh.obj" scale="1. 1. 1."/>
      </geometry>
    </collision>
  </link>
  <link name="right_outer_finger">
    <inertial>
      <origin xyz="0.0003012 0.0373908 -0.0208027" rpy="0. 0. 0."/>
      <mass value="0.0226142"/>
      <inertia ixx="0.0000153" ixy="0." ixz="-0." iyy="0.0000062" iyz="0.0000068" izz="0.0000116"/>
    </inertial>
    <visual>
      <origin xyz="0. -0. -0." rpy="0. 0. 0."/>
      <geometry>
        <mesh filename="file:///home/gbt/ws/urdf/gbt-c5a_wrist_camera_gripper/meshes/right_outer_finger_visuals_robotiq_arg2f_140_outer_finger_node_STL_BINARY__mesh.obj" scale="1. 1. 1."/>
      </geometry>
    </visual>
    <visual>
      <origin xyz="0. -0. -0." rpy="0. 0. 0."/>
      <geometry>
        <mesh filename="file:///home/gbt/ws/urdf/gbt-c5a_wrist_camera_gripper/meshes/right_outer_finger_collisions_robotiq_arg2f_140_outer_finger_node_STL_BINARY__mesh.obj" scale="1. 1. 1."/>
      </geometry>
    </visual>
    <collision>
      <origin xyz="0. -0. -0." rpy="0. 0. 0."/>
      <geometry>
        <mesh filename="file:///home/gbt/ws/urdf/gbt-c5a_wrist_camera_gripper/meshes/right_outer_finger_collisions_robotiq_arg2f_140_outer_finger_node_STL_BINARY__mesh.obj" scale="1. 1. 1."/>
      </geometry>
    </collision>
  </link>
  <link name="right_outer_knuckle">
    <inertial>
      <origin xyz="-0.0002 0.0199436 0.0292245" rpy="0. 0. 0."/>
      <mass value="0.008532"/>
      <inertia ixx="0.0000029" ixy="0." ixz="0." iyy="0.0000019" iyz="-0.0000012" izz="0.0000012"/>
    </inertial>
    <visual>
      <origin xyz="-0. -0.0000001 -0. " rpy="-0.0000001 -0.0000004 0.0000001"/>
      <geometry>
        <mesh filename="file:///home/gbt/ws/urdf/gbt-c5a_wrist_camera_gripper/meshes/right_outer_knuckle_visuals_robotiq_arg2f_140_outer_knuckle_node_STL_BINARY__mesh.obj" scale="1. 1. 1."/>
      </geometry>
    </visual>
    <visual>
      <origin xyz="-0. -0.0000001 -0. " rpy="-0.0000001 -0.0000004 0.0000001"/>
      <geometry>
        <mesh filename="file:///home/gbt/ws/urdf/gbt-c5a_wrist_camera_gripper/meshes/right_outer_knuckle_collisions_robotiq_arg2f_140_outer_knuckle_node_STL_BINARY__mesh.obj" scale="1. 1. 1."/>
      </geometry>
    </visual>
    <collision>
      <origin xyz="-0. -0.0000001 -0. " rpy="-0.0000001 -0.0000004 0.0000001"/>
      <geometry>
        <mesh filename="file:///home/gbt/ws/urdf/gbt-c5a_wrist_camera_gripper/meshes/right_outer_knuckle_collisions_robotiq_arg2f_140_outer_knuckle_node_STL_BINARY__mesh.obj" scale="1. 1. 1."/>
      </geometry>
    </collision>
  </link>
  <link name="tcp">
    <inertial>
      <origin xyz="0. 0. 0." rpy="0. 0. 0."/>
      <mass value="1."/>
      <inertia ixx="0.0001" ixy="0." ixz="0." iyy="0.0001" iyz="0." izz="0.0001"/>
    </inertial>
  </link>
</robot>
